Watching for file changes with StatReloader
Watching for file changes with StatReloader
Internal Server Error: /
Traceback (most recent call last):
  File "/usr/local/lib/python3.8/site-packages/django/db/backends/utils.py", line 86, in _execute
    return self.cursor.execute(sql, params)
psycopg2.errors.UndefinedTable: relation "jobs_job" does not exist
LINE 1: ...t", "jobs_job"."filled", "jobs_job"."salary" FROM "jobs_job"...
                                                             ^


The above exception was the direct cause of the following exception:

Traceback (most recent call last):
  File "/usr/local/lib/python3.8/site-packages/django/core/handlers/exception.py", line 34, in inner
    response = get_response(request)
  File "/usr/local/lib/python3.8/site-packages/django/core/handlers/base.py", line 145, in _get_response
    response = self.process_exception_by_middleware(e, request)
  File "/usr/local/lib/python3.8/site-packages/django/core/handlers/base.py", line 143, in _get_response
    response = response.render()
  File "/usr/local/lib/python3.8/site-packages/django/template/response.py", line 105, in render
    self.content = self.rendered_content
  File "/usr/local/lib/python3.8/site-packages/django/template/response.py", line 83, in rendered_content
    return template.render(context, self._request)
  File "/usr/local/lib/python3.8/site-packages/django/template/backends/django.py", line 61, in render
    return self.template.render(context)
  File "/usr/local/lib/python3.8/site-packages/django/template/base.py", line 171, in render
    return self._render(context)
  File "/usr/local/lib/python3.8/site-packages/django/template/base.py", line 163, in _render
    return self.nodelist.render(context)
  File "/usr/local/lib/python3.8/site-packages/django/template/base.py", line 936, in render
    bit = node.render_annotated(context)
  File "/usr/local/lib/python3.8/site-packages/django/template/base.py", line 903, in render_annotated
    return self.render(context)
  File "/usr/local/lib/python3.8/site-packages/django/template/loader_tags.py", line 150, in render
    return compiled_parent._render(context)
  File "/usr/local/lib/python3.8/site-packages/django/template/base.py", line 163, in _render
    return self.nodelist.render(context)
  File "/usr/local/lib/python3.8/site-packages/django/template/base.py", line 936, in render
    bit = node.render_annotated(context)
  File "/usr/local/lib/python3.8/site-packages/django/template/base.py", line 903, in render_annotated
    return self.render(context)
  File "/usr/local/lib/python3.8/site-packages/django/template/loader_tags.py", line 62, in render
    result = block.nodelist.render(context)
  File "/usr/local/lib/python3.8/site-packages/django/template/base.py", line 936, in render
    bit = node.render_annotated(context)
  File "/usr/local/lib/python3.8/site-packages/django/template/base.py", line 903, in render_annotated
    return self.render(context)
  File "/usr/local/lib/python3.8/site-packages/django/template/defaulttags.py", line 166, in render
    len_values = len(values)
  File "/usr/local/lib/python3.8/site-packages/django/db/models/query.py", line 258, in __len__
    self._fetch_all()
  File "/usr/local/lib/python3.8/site-packages/django/db/models/query.py", line 1261, in _fetch_all
    self._result_cache = list(self._iterable_class(self))
  File "/usr/local/lib/python3.8/site-packages/django/db/models/query.py", line 57, in __iter__
    results = compiler.execute_sql(chunked_fetch=self.chunked_fetch, chunk_size=self.chunk_size)
  File "/usr/local/lib/python3.8/site-packages/django/db/models/sql/compiler.py", line 1151, in execute_sql
    cursor.execute(sql, params)
  File "/usr/local/lib/python3.8/site-packages/django/db/backends/utils.py", line 100, in execute
    return super().execute(sql, params)
  File "/usr/local/lib/python3.8/site-packages/django/db/backends/utils.py", line 68, in execute
    return self._execute_with_wrappers(sql, params, many=False, executor=self._execute)
  File "/usr/local/lib/python3.8/site-packages/django/db/backends/utils.py", line 77, in _execute_with_wrappers
    return executor(sql, params, many, context)
  File "/usr/local/lib/python3.8/site-packages/django/db/backends/utils.py", line 86, in _execute
    return self.cursor.execute(sql, params)
  File "/usr/local/lib/python3.8/site-packages/django/db/utils.py", line 90, in __exit__
    raise dj_exc_value.with_traceback(traceback) from exc_value
  File "/usr/local/lib/python3.8/site-packages/django/db/backends/utils.py", line 86, in _execute
    return self.cursor.execute(sql, params)
django.db.utils.ProgrammingError: relation "jobs_job" does not exist
LINE 1: ...t", "jobs_job"."filled", "jobs_job"."salary" FROM "jobs_job"...
                                                             ^

Internal Server Error: /
Traceback (most recent call last):
  File "/usr/local/lib/python3.8/site-packages/django/db/backends/utils.py", line 86, in _execute
    return self.cursor.execute(sql, params)
psycopg2.errors.UndefinedTable: relation "jobs_job" does not exist
LINE 1: ...t", "jobs_job"."filled", "jobs_job"."salary" FROM "jobs_job"...
                                                             ^


The above exception was the direct cause of the following exception:

Traceback (most recent call last):
  File "/usr/local/lib/python3.8/site-packages/django/core/handlers/exception.py", line 34, in inner
    response = get_response(request)
  File "/usr/local/lib/python3.8/site-packages/django/core/handlers/base.py", line 145, in _get_response
    response = self.process_exception_by_middleware(e, request)
  File "/usr/local/lib/python3.8/site-packages/django/core/handlers/base.py", line 143, in _get_response
    response = response.render()
  File "/usr/local/lib/python3.8/site-packages/django/template/response.py", line 105, in render
    self.content = self.rendered_content
  File "/usr/local/lib/python3.8/site-packages/django/template/response.py", line 83, in rendered_content
    return template.render(context, self._request)
  File "/usr/local/lib/python3.8/site-packages/django/template/backends/django.py", line 61, in render
    return self.template.render(context)
  File "/usr/local/lib/python3.8/site-packages/django/template/base.py", line 171, in render
    return self._render(context)
  File "/usr/local/lib/python3.8/site-packages/django/template/base.py", line 163, in _render
    return self.nodelist.render(context)
  File "/usr/local/lib/python3.8/site-packages/django/template/base.py", line 936, in render
    bit = node.render_annotated(context)
  File "/usr/local/lib/python3.8/site-packages/django/template/base.py", line 903, in render_annotated
    return self.render(context)
  File "/usr/local/lib/python3.8/site-packages/django/template/loader_tags.py", line 150, in render
    return compiled_parent._render(context)
  File "/usr/local/lib/python3.8/site-packages/django/template/base.py", line 163, in _render
    return self.nodelist.render(context)
  File "/usr/local/lib/python3.8/site-packages/django/template/base.py", line 936, in render
    bit = node.render_annotated(context)
  File "/usr/local/lib/python3.8/site-packages/django/template/base.py", line 903, in render_annotated
    return self.render(context)
  File "/usr/local/lib/python3.8/site-packages/django/template/loader_tags.py", line 62, in render
    result = block.nodelist.render(context)
  File "/usr/local/lib/python3.8/site-packages/django/template/base.py", line 936, in render
    bit = node.render_annotated(context)
  File "/usr/local/lib/python3.8/site-packages/django/template/base.py", line 903, in render_annotated
    return self.render(context)
  File "/usr/local/lib/python3.8/site-packages/django/template/defaulttags.py", line 166, in render
    len_values = len(values)
  File "/usr/local/lib/python3.8/site-packages/django/db/models/query.py", line 258, in __len__
    self._fetch_all()
  File "/usr/local/lib/python3.8/site-packages/django/db/models/query.py", line 1261, in _fetch_all
    self._result_cache = list(self._iterable_class(self))
  File "/usr/local/lib/python3.8/site-packages/django/db/models/query.py", line 57, in __iter__
    results = compiler.execute_sql(chunked_fetch=self.chunked_fetch, chunk_size=self.chunk_size)
  File "/usr/local/lib/python3.8/site-packages/django/db/models/sql/compiler.py", line 1151, in execute_sql
    cursor.execute(sql, params)
  File "/usr/local/lib/python3.8/site-packages/django/db/backends/utils.py", line 100, in execute
    return super().execute(sql, params)
  File "/usr/local/lib/python3.8/site-packages/django/db/backends/utils.py", line 68, in execute
    return self._execute_with_wrappers(sql, params, many=False, executor=self._execute)
  File "/usr/local/lib/python3.8/site-packages/django/db/backends/utils.py", line 77, in _execute_with_wrappers
    return executor(sql, params, many, context)
  File "/usr/local/lib/python3.8/site-packages/django/db/backends/utils.py", line 86, in _execute
    return self.cursor.execute(sql, params)
  File "/usr/local/lib/python3.8/site-packages/django/db/utils.py", line 90, in __exit__
    raise dj_exc_value.with_traceback(traceback) from exc_value
  File "/usr/local/lib/python3.8/site-packages/django/db/backends/utils.py", line 86, in _execute
    return self.cursor.execute(sql, params)
django.db.utils.ProgrammingError: relation "jobs_job" does not exist
LINE 1: ...t", "jobs_job"."filled", "jobs_job"."salary" FROM "jobs_job"...
                                                             ^

"GET / HTTP/1.1" 500 209133
"GET / HTTP/1.1" 500 209133
Internal Server Error: /admin/
Traceback (most recent call last):
  File "/usr/local/lib/python3.8/site-packages/django/contrib/sessions/backends/base.py", line 199, in _get_session
    return self._session_cache
AttributeError: 'SessionStore' object has no attribute '_session_cache'

During handling of the above exception, another exception occurred:

Traceback (most recent call last):
  File "/usr/local/lib/python3.8/site-packages/django/db/backends/utils.py", line 86, in _execute
    return self.cursor.execute(sql, params)
psycopg2.errors.UndefinedTable: relation "django_session" does not exist
LINE 1: ...ession_data", "django_session"."expire_date" FROM "django_se...
                                                             ^


The above exception was the direct cause of the following exception:

Traceback (most recent call last):
  File "/usr/local/lib/python3.8/site-packages/django/core/handlers/exception.py", line 34, in inner
    response = get_response(request)
  File "/usr/local/lib/python3.8/site-packages/django/core/handlers/base.py", line 115, in _get_response
    response = self.process_exception_by_middleware(e, request)
  File "/usr/local/lib/python3.8/site-packages/django/core/handlers/base.py", line 113, in _get_response
    response = wrapped_callback(request, *callback_args, **callback_kwargs)
  File "/usr/local/lib/python3.8/site-packages/django/contrib/admin/sites.py", line 249, in wrapper
    return self.admin_view(view, cacheable)(*args, **kwargs)
  File "/usr/local/lib/python3.8/site-packages/django/utils/decorators.py", line 130, in _wrapped_view
    response = view_func(request, *args, **kwargs)
  File "/usr/local/lib/python3.8/site-packages/django/views/decorators/cache.py", line 44, in _wrapped_view_func
    response = view_func(request, *args, **kwargs)
  File "/usr/local/lib/python3.8/site-packages/django/contrib/admin/sites.py", line 220, in inner
    if not self.has_permission(request):
  File "/usr/local/lib/python3.8/site-packages/django/contrib/admin/sites.py", line 194, in has_permission
    return request.user.is_active and request.user.is_staff
  File "/usr/local/lib/python3.8/site-packages/django/utils/functional.py", line 224, in inner
    self._setup()
  File "/usr/local/lib/python3.8/site-packages/django/utils/functional.py", line 360, in _setup
    self._wrapped = self._setupfunc()
  File "/usr/local/lib/python3.8/site-packages/django/contrib/auth/middleware.py", line 24, in <lambda>
    request.user = SimpleLazyObject(lambda: get_user(request))
  File "/usr/local/lib/python3.8/site-packages/django/contrib/auth/middleware.py", line 12, in get_user
    request._cached_user = auth.get_user(request)
  File "/usr/local/lib/python3.8/site-packages/django/contrib/auth/__init__.py", line 173, in get_user
    user_id = _get_user_session_key(request)
  File "/usr/local/lib/python3.8/site-packages/django/contrib/auth/__init__.py", line 58, in _get_user_session_key
    return get_user_model()._meta.pk.to_python(request.session[SESSION_KEY])
  File "/usr/local/lib/python3.8/site-packages/django/contrib/sessions/backends/base.py", line 64, in __getitem__
    return self._session[key]
  File "/usr/local/lib/python3.8/site-packages/django/contrib/sessions/backends/base.py", line 204, in _get_session
    self._session_cache = self.load()
  File "/usr/local/lib/python3.8/site-packages/django/contrib/sessions/backends/db.py", line 43, in load
    s = self._get_session_from_db()
  File "/usr/local/lib/python3.8/site-packages/django/contrib/sessions/backends/db.py", line 32, in _get_session_from_db
    return self.model.objects.get(
  File "/usr/local/lib/python3.8/site-packages/django/db/models/manager.py", line 82, in manager_method
    return getattr(self.get_queryset(), name)(*args, **kwargs)
  File "/usr/local/lib/python3.8/site-packages/django/db/models/query.py", line 411, in get
    num = len(clone)
  File "/usr/local/lib/python3.8/site-packages/django/db/models/query.py", line 258, in __len__
    self._fetch_all()
  File "/usr/local/lib/python3.8/site-packages/django/db/models/query.py", line 1261, in _fetch_all
    self._result_cache = list(self._iterable_class(self))
  File "/usr/local/lib/python3.8/site-packages/django/db/models/query.py", line 57, in __iter__
    results = compiler.execute_sql(chunked_fetch=self.chunked_fetch, chunk_size=self.chunk_size)
  File "/usr/local/lib/python3.8/site-packages/django/db/models/sql/compiler.py", line 1151, in execute_sql
    cursor.execute(sql, params)
  File "/usr/local/lib/python3.8/site-packages/django/db/backends/utils.py", line 100, in execute
    return super().execute(sql, params)
  File "/usr/local/lib/python3.8/site-packages/django/db/backends/utils.py", line 68, in execute
    return self._execute_with_wrappers(sql, params, many=False, executor=self._execute)
  File "/usr/local/lib/python3.8/site-packages/django/db/backends/utils.py", line 77, in _execute_with_wrappers
    return executor(sql, params, many, context)
  File "/usr/local/lib/python3.8/site-packages/django/db/backends/utils.py", line 86, in _execute
    return self.cursor.execute(sql, params)
  File "/usr/local/lib/python3.8/site-packages/django/db/utils.py", line 90, in __exit__
    raise dj_exc_value.with_traceback(traceback) from exc_value
  File "/usr/local/lib/python3.8/site-packages/django/db/backends/utils.py", line 86, in _execute
    return self.cursor.execute(sql, params)
django.db.utils.ProgrammingError: relation "django_session" does not exist
LINE 1: ...ession_data", "django_session"."expire_date" FROM "django_se...
                                                             ^

Internal Server Error: /admin/
Traceback (most recent call last):
  File "/usr/local/lib/python3.8/site-packages/django/contrib/sessions/backends/base.py", line 199, in _get_session
    return self._session_cache
AttributeError: 'SessionStore' object has no attribute '_session_cache'

During handling of the above exception, another exception occurred:

Traceback (most recent call last):
  File "/usr/local/lib/python3.8/site-packages/django/db/backends/utils.py", line 86, in _execute
    return self.cursor.execute(sql, params)
psycopg2.errors.UndefinedTable: relation "django_session" does not exist
LINE 1: ...ession_data", "django_session"."expire_date" FROM "django_se...
                                                             ^


The above exception was the direct cause of the following exception:

Traceback (most recent call last):
  File "/usr/local/lib/python3.8/site-packages/django/core/handlers/exception.py", line 34, in inner
    response = get_response(request)
  File "/usr/local/lib/python3.8/site-packages/django/core/handlers/base.py", line 115, in _get_response
    response = self.process_exception_by_middleware(e, request)
  File "/usr/local/lib/python3.8/site-packages/django/core/handlers/base.py", line 113, in _get_response
    response = wrapped_callback(request, *callback_args, **callback_kwargs)
  File "/usr/local/lib/python3.8/site-packages/django/contrib/admin/sites.py", line 249, in wrapper
    return self.admin_view(view, cacheable)(*args, **kwargs)
  File "/usr/local/lib/python3.8/site-packages/django/utils/decorators.py", line 130, in _wrapped_view
    response = view_func(request, *args, **kwargs)
  File "/usr/local/lib/python3.8/site-packages/django/views/decorators/cache.py", line 44, in _wrapped_view_func
    response = view_func(request, *args, **kwargs)
  File "/usr/local/lib/python3.8/site-packages/django/contrib/admin/sites.py", line 220, in inner
    if not self.has_permission(request):
  File "/usr/local/lib/python3.8/site-packages/django/contrib/admin/sites.py", line 194, in has_permission
    return request.user.is_active and request.user.is_staff
  File "/usr/local/lib/python3.8/site-packages/django/utils/functional.py", line 224, in inner
    self._setup()
  File "/usr/local/lib/python3.8/site-packages/django/utils/functional.py", line 360, in _setup
    self._wrapped = self._setupfunc()
  File "/usr/local/lib/python3.8/site-packages/django/contrib/auth/middleware.py", line 24, in <lambda>
    request.user = SimpleLazyObject(lambda: get_user(request))
  File "/usr/local/lib/python3.8/site-packages/django/contrib/auth/middleware.py", line 12, in get_user
    request._cached_user = auth.get_user(request)
  File "/usr/local/lib/python3.8/site-packages/django/contrib/auth/__init__.py", line 173, in get_user
    user_id = _get_user_session_key(request)
  File "/usr/local/lib/python3.8/site-packages/django/contrib/auth/__init__.py", line 58, in _get_user_session_key
    return get_user_model()._meta.pk.to_python(request.session[SESSION_KEY])
  File "/usr/local/lib/python3.8/site-packages/django/contrib/sessions/backends/base.py", line 64, in __getitem__
    return self._session[key]
  File "/usr/local/lib/python3.8/site-packages/django/contrib/sessions/backends/base.py", line 204, in _get_session
    self._session_cache = self.load()
  File "/usr/local/lib/python3.8/site-packages/django/contrib/sessions/backends/db.py", line 43, in load
    s = self._get_session_from_db()
  File "/usr/local/lib/python3.8/site-packages/django/contrib/sessions/backends/db.py", line 32, in _get_session_from_db
    return self.model.objects.get(
  File "/usr/local/lib/python3.8/site-packages/django/db/models/manager.py", line 82, in manager_method
    return getattr(self.get_queryset(), name)(*args, **kwargs)
  File "/usr/local/lib/python3.8/site-packages/django/db/models/query.py", line 411, in get
    num = len(clone)
  File "/usr/local/lib/python3.8/site-packages/django/db/models/query.py", line 258, in __len__
    self._fetch_all()
  File "/usr/local/lib/python3.8/site-packages/django/db/models/query.py", line 1261, in _fetch_all
    self._result_cache = list(self._iterable_class(self))
  File "/usr/local/lib/python3.8/site-packages/django/db/models/query.py", line 57, in __iter__
    results = compiler.execute_sql(chunked_fetch=self.chunked_fetch, chunk_size=self.chunk_size)
  File "/usr/local/lib/python3.8/site-packages/django/db/models/sql/compiler.py", line 1151, in execute_sql
    cursor.execute(sql, params)
  File "/usr/local/lib/python3.8/site-packages/django/db/backends/utils.py", line 100, in execute
    return super().execute(sql, params)
  File "/usr/local/lib/python3.8/site-packages/django/db/backends/utils.py", line 68, in execute
    return self._execute_with_wrappers(sql, params, many=False, executor=self._execute)
  File "/usr/local/lib/python3.8/site-packages/django/db/backends/utils.py", line 77, in _execute_with_wrappers
    return executor(sql, params, many, context)
  File "/usr/local/lib/python3.8/site-packages/django/db/backends/utils.py", line 86, in _execute
    return self.cursor.execute(sql, params)
  File "/usr/local/lib/python3.8/site-packages/django/db/utils.py", line 90, in __exit__
    raise dj_exc_value.with_traceback(traceback) from exc_value
  File "/usr/local/lib/python3.8/site-packages/django/db/backends/utils.py", line 86, in _execute
    return self.cursor.execute(sql, params)
django.db.utils.ProgrammingError: relation "django_session" does not exist
LINE 1: ...ession_data", "django_session"."expire_date" FROM "django_se...
                                                             ^

"GET /admin/ HTTP/1.1" 500 192365
"GET /admin/ HTTP/1.1" 500 192365
Internal Server Error: /admin/
Traceback (most recent call last):
  File "/usr/local/lib/python3.8/site-packages/django/contrib/sessions/backends/base.py", line 199, in _get_session
    return self._session_cache
AttributeError: 'SessionStore' object has no attribute '_session_cache'

During handling of the above exception, another exception occurred:

Traceback (most recent call last):
  File "/usr/local/lib/python3.8/site-packages/django/db/backends/utils.py", line 86, in _execute
    return self.cursor.execute(sql, params)
psycopg2.errors.UndefinedTable: relation "django_session" does not exist
LINE 1: ...ession_data", "django_session"."expire_date" FROM "django_se...
                                                             ^


The above exception was the direct cause of the following exception:

Traceback (most recent call last):
  File "/usr/local/lib/python3.8/site-packages/django/core/handlers/exception.py", line 34, in inner
    response = get_response(request)
  File "/usr/local/lib/python3.8/site-packages/django/core/handlers/base.py", line 115, in _get_response
    response = self.process_exception_by_middleware(e, request)
  File "/usr/local/lib/python3.8/site-packages/django/core/handlers/base.py", line 113, in _get_response
    response = wrapped_callback(request, *callback_args, **callback_kwargs)
  File "/usr/local/lib/python3.8/site-packages/django/contrib/admin/sites.py", line 249, in wrapper
    return self.admin_view(view, cacheable)(*args, **kwargs)
  File "/usr/local/lib/python3.8/site-packages/django/utils/decorators.py", line 130, in _wrapped_view
    response = view_func(request, *args, **kwargs)
  File "/usr/local/lib/python3.8/site-packages/django/views/decorators/cache.py", line 44, in _wrapped_view_func
    response = view_func(request, *args, **kwargs)
  File "/usr/local/lib/python3.8/site-packages/django/contrib/admin/sites.py", line 220, in inner
    if not self.has_permission(request):
  File "/usr/local/lib/python3.8/site-packages/django/contrib/admin/sites.py", line 194, in has_permission
    return request.user.is_active and request.user.is_staff
  File "/usr/local/lib/python3.8/site-packages/django/utils/functional.py", line 224, in inner
    self._setup()
  File "/usr/local/lib/python3.8/site-packages/django/utils/functional.py", line 360, in _setup
    self._wrapped = self._setupfunc()
  File "/usr/local/lib/python3.8/site-packages/django/contrib/auth/middleware.py", line 24, in <lambda>
    request.user = SimpleLazyObject(lambda: get_user(request))
  File "/usr/local/lib/python3.8/site-packages/django/contrib/auth/middleware.py", line 12, in get_user
    request._cached_user = auth.get_user(request)
  File "/usr/local/lib/python3.8/site-packages/django/contrib/auth/__init__.py", line 173, in get_user
    user_id = _get_user_session_key(request)
  File "/usr/local/lib/python3.8/site-packages/django/contrib/auth/__init__.py", line 58, in _get_user_session_key
    return get_user_model()._meta.pk.to_python(request.session[SESSION_KEY])
  File "/usr/local/lib/python3.8/site-packages/django/contrib/sessions/backends/base.py", line 64, in __getitem__
    return self._session[key]
  File "/usr/local/lib/python3.8/site-packages/django/contrib/sessions/backends/base.py", line 204, in _get_session
    self._session_cache = self.load()
  File "/usr/local/lib/python3.8/site-packages/django/contrib/sessions/backends/db.py", line 43, in load
    s = self._get_session_from_db()
  File "/usr/local/lib/python3.8/site-packages/django/contrib/sessions/backends/db.py", line 32, in _get_session_from_db
    return self.model.objects.get(
  File "/usr/local/lib/python3.8/site-packages/django/db/models/manager.py", line 82, in manager_method
    return getattr(self.get_queryset(), name)(*args, **kwargs)
  File "/usr/local/lib/python3.8/site-packages/django/db/models/query.py", line 411, in get
    num = len(clone)
  File "/usr/local/lib/python3.8/site-packages/django/db/models/query.py", line 258, in __len__
    self._fetch_all()
  File "/usr/local/lib/python3.8/site-packages/django/db/models/query.py", line 1261, in _fetch_all
    self._result_cache = list(self._iterable_class(self))
  File "/usr/local/lib/python3.8/site-packages/django/db/models/query.py", line 57, in __iter__
    results = compiler.execute_sql(chunked_fetch=self.chunked_fetch, chunk_size=self.chunk_size)
  File "/usr/local/lib/python3.8/site-packages/django/db/models/sql/compiler.py", line 1151, in execute_sql
    cursor.execute(sql, params)
  File "/usr/local/lib/python3.8/site-packages/django/db/backends/utils.py", line 100, in execute
    return super().execute(sql, params)
  File "/usr/local/lib/python3.8/site-packages/django/db/backends/utils.py", line 68, in execute
    return self._execute_with_wrappers(sql, params, many=False, executor=self._execute)
  File "/usr/local/lib/python3.8/site-packages/django/db/backends/utils.py", line 77, in _execute_with_wrappers
    return executor(sql, params, many, context)
  File "/usr/local/lib/python3.8/site-packages/django/db/backends/utils.py", line 86, in _execute
    return self.cursor.execute(sql, params)
  File "/usr/local/lib/python3.8/site-packages/django/db/utils.py", line 90, in __exit__
    raise dj_exc_value.with_traceback(traceback) from exc_value
  File "/usr/local/lib/python3.8/site-packages/django/db/backends/utils.py", line 86, in _execute
    return self.cursor.execute(sql, params)
django.db.utils.ProgrammingError: relation "django_session" does not exist
LINE 1: ...ession_data", "django_session"."expire_date" FROM "django_se...
                                                             ^

Internal Server Error: /admin/
Traceback (most recent call last):
  File "/usr/local/lib/python3.8/site-packages/django/contrib/sessions/backends/base.py", line 199, in _get_session
    return self._session_cache
AttributeError: 'SessionStore' object has no attribute '_session_cache'

During handling of the above exception, another exception occurred:

Traceback (most recent call last):
  File "/usr/local/lib/python3.8/site-packages/django/db/backends/utils.py", line 86, in _execute
    return self.cursor.execute(sql, params)
psycopg2.errors.UndefinedTable: relation "django_session" does not exist
LINE 1: ...ession_data", "django_session"."expire_date" FROM "django_se...
                                                             ^


The above exception was the direct cause of the following exception:

Traceback (most recent call last):
  File "/usr/local/lib/python3.8/site-packages/django/core/handlers/exception.py", line 34, in inner
    response = get_response(request)
  File "/usr/local/lib/python3.8/site-packages/django/core/handlers/base.py", line 115, in _get_response
    response = self.process_exception_by_middleware(e, request)
  File "/usr/local/lib/python3.8/site-packages/django/core/handlers/base.py", line 113, in _get_response
    response = wrapped_callback(request, *callback_args, **callback_kwargs)
  File "/usr/local/lib/python3.8/site-packages/django/contrib/admin/sites.py", line 249, in wrapper
    return self.admin_view(view, cacheable)(*args, **kwargs)
  File "/usr/local/lib/python3.8/site-packages/django/utils/decorators.py", line 130, in _wrapped_view
    response = view_func(request, *args, **kwargs)
  File "/usr/local/lib/python3.8/site-packages/django/views/decorators/cache.py", line 44, in _wrapped_view_func
    response = view_func(request, *args, **kwargs)
  File "/usr/local/lib/python3.8/site-packages/django/contrib/admin/sites.py", line 220, in inner
    if not self.has_permission(request):
  File "/usr/local/lib/python3.8/site-packages/django/contrib/admin/sites.py", line 194, in has_permission
    return request.user.is_active and request.user.is_staff
  File "/usr/local/lib/python3.8/site-packages/django/utils/functional.py", line 224, in inner
    self._setup()
  File "/usr/local/lib/python3.8/site-packages/django/utils/functional.py", line 360, in _setup
    self._wrapped = self._setupfunc()
  File "/usr/local/lib/python3.8/site-packages/django/contrib/auth/middleware.py", line 24, in <lambda>
    request.user = SimpleLazyObject(lambda: get_user(request))
  File "/usr/local/lib/python3.8/site-packages/django/contrib/auth/middleware.py", line 12, in get_user
    request._cached_user = auth.get_user(request)
  File "/usr/local/lib/python3.8/site-packages/django/contrib/auth/__init__.py", line 173, in get_user
    user_id = _get_user_session_key(request)
  File "/usr/local/lib/python3.8/site-packages/django/contrib/auth/__init__.py", line 58, in _get_user_session_key
    return get_user_model()._meta.pk.to_python(request.session[SESSION_KEY])
  File "/usr/local/lib/python3.8/site-packages/django/contrib/sessions/backends/base.py", line 64, in __getitem__
    return self._session[key]
  File "/usr/local/lib/python3.8/site-packages/django/contrib/sessions/backends/base.py", line 204, in _get_session
    self._session_cache = self.load()
  File "/usr/local/lib/python3.8/site-packages/django/contrib/sessions/backends/db.py", line 43, in load
    s = self._get_session_from_db()
  File "/usr/local/lib/python3.8/site-packages/django/contrib/sessions/backends/db.py", line 32, in _get_session_from_db
    return self.model.objects.get(
  File "/usr/local/lib/python3.8/site-packages/django/db/models/manager.py", line 82, in manager_method
    return getattr(self.get_queryset(), name)(*args, **kwargs)
  File "/usr/local/lib/python3.8/site-packages/django/db/models/query.py", line 411, in get
    num = len(clone)
  File "/usr/local/lib/python3.8/site-packages/django/db/models/query.py", line 258, in __len__
    self._fetch_all()
  File "/usr/local/lib/python3.8/site-packages/django/db/models/query.py", line 1261, in _fetch_all
    self._result_cache = list(self._iterable_class(self))
  File "/usr/local/lib/python3.8/site-packages/django/db/models/query.py", line 57, in __iter__
    results = compiler.execute_sql(chunked_fetch=self.chunked_fetch, chunk_size=self.chunk_size)
  File "/usr/local/lib/python3.8/site-packages/django/db/models/sql/compiler.py", line 1151, in execute_sql
    cursor.execute(sql, params)
  File "/usr/local/lib/python3.8/site-packages/django/db/backends/utils.py", line 100, in execute
    return super().execute(sql, params)
  File "/usr/local/lib/python3.8/site-packages/django/db/backends/utils.py", line 68, in execute
    return self._execute_with_wrappers(sql, params, many=False, executor=self._execute)
  File "/usr/local/lib/python3.8/site-packages/django/db/backends/utils.py", line 77, in _execute_with_wrappers
    return executor(sql, params, many, context)
  File "/usr/local/lib/python3.8/site-packages/django/db/backends/utils.py", line 86, in _execute
    return self.cursor.execute(sql, params)
  File "/usr/local/lib/python3.8/site-packages/django/db/utils.py", line 90, in __exit__
    raise dj_exc_value.with_traceback(traceback) from exc_value
  File "/usr/local/lib/python3.8/site-packages/django/db/backends/utils.py", line 86, in _execute
    return self.cursor.execute(sql, params)
django.db.utils.ProgrammingError: relation "django_session" does not exist
LINE 1: ...ession_data", "django_session"."expire_date" FROM "django_se...
                                                             ^

"GET /admin/ HTTP/1.1" 500 192372
"GET /admin/ HTTP/1.1" 500 192372
"GET /admin/ HTTP/1.1" 302 0
"GET /admin/ HTTP/1.1" 302 0
"GET /admin/login/?next=/admin/ HTTP/1.1" 200 1918
"GET /admin/login/?next=/admin/ HTTP/1.1" 200 1918
"GET /static/admin/css/login.css HTTP/1.1" 200 1233
"GET /static/admin/css/login.css HTTP/1.1" 200 1233
"GET /static/admin/css/base.css HTTP/1.1" 200 16378
"GET /static/admin/css/base.css HTTP/1.1" 200 16378
"GET /static/admin/css/responsive.css HTTP/1.1" 200 18052
"GET /static/admin/css/responsive.css HTTP/1.1" 200 18052
"GET /static/admin/css/fonts.css HTTP/1.1" 200 423
"GET /static/admin/css/fonts.css HTTP/1.1" 200 423
"GET /static/admin/fonts/Roboto-Regular-webfont.woff HTTP/1.1" 200 85876
"GET /static/admin/fonts/Roboto-Regular-webfont.woff HTTP/1.1" 200 85876
"GET /static/admin/fonts/Roboto-Light-webfont.woff HTTP/1.1" 200 85692
"GET /static/admin/fonts/Roboto-Light-webfont.woff HTTP/1.1" 200 85692
Internal Server Error: /
Traceback (most recent call last):
  File "/usr/local/lib/python3.8/site-packages/django/db/backends/utils.py", line 86, in _execute
    return self.cursor.execute(sql, params)
psycopg2.errors.UndefinedTable: relation "jobs_job" does not exist
LINE 1: ...t", "jobs_job"."filled", "jobs_job"."salary" FROM "jobs_job"...
                                                             ^


The above exception was the direct cause of the following exception:

Traceback (most recent call last):
  File "/usr/local/lib/python3.8/site-packages/django/core/handlers/exception.py", line 34, in inner
    response = get_response(request)
  File "/usr/local/lib/python3.8/site-packages/django/core/handlers/base.py", line 145, in _get_response
    response = self.process_exception_by_middleware(e, request)
  File "/usr/local/lib/python3.8/site-packages/django/core/handlers/base.py", line 143, in _get_response
    response = response.render()
  File "/usr/local/lib/python3.8/site-packages/django/template/response.py", line 105, in render
    self.content = self.rendered_content
  File "/usr/local/lib/python3.8/site-packages/django/template/response.py", line 83, in rendered_content
    return template.render(context, self._request)
  File "/usr/local/lib/python3.8/site-packages/django/template/backends/django.py", line 61, in render
    return self.template.render(context)
  File "/usr/local/lib/python3.8/site-packages/django/template/base.py", line 171, in render
    return self._render(context)
  File "/usr/local/lib/python3.8/site-packages/django/template/base.py", line 163, in _render
    return self.nodelist.render(context)
  File "/usr/local/lib/python3.8/site-packages/django/template/base.py", line 936, in render
    bit = node.render_annotated(context)
  File "/usr/local/lib/python3.8/site-packages/django/template/base.py", line 903, in render_annotated
    return self.render(context)
  File "/usr/local/lib/python3.8/site-packages/django/template/loader_tags.py", line 150, in render
    return compiled_parent._render(context)
  File "/usr/local/lib/python3.8/site-packages/django/template/base.py", line 163, in _render
    return self.nodelist.render(context)
  File "/usr/local/lib/python3.8/site-packages/django/template/base.py", line 936, in render
    bit = node.render_annotated(context)
  File "/usr/local/lib/python3.8/site-packages/django/template/base.py", line 903, in render_annotated
    return self.render(context)
  File "/usr/local/lib/python3.8/site-packages/django/template/loader_tags.py", line 62, in render
    result = block.nodelist.render(context)
  File "/usr/local/lib/python3.8/site-packages/django/template/base.py", line 936, in render
    bit = node.render_annotated(context)
  File "/usr/local/lib/python3.8/site-packages/django/template/base.py", line 903, in render_annotated
    return self.render(context)
  File "/usr/local/lib/python3.8/site-packages/django/template/defaulttags.py", line 166, in render
    len_values = len(values)
  File "/usr/local/lib/python3.8/site-packages/django/db/models/query.py", line 258, in __len__
    self._fetch_all()
  File "/usr/local/lib/python3.8/site-packages/django/db/models/query.py", line 1261, in _fetch_all
    self._result_cache = list(self._iterable_class(self))
  File "/usr/local/lib/python3.8/site-packages/django/db/models/query.py", line 57, in __iter__
    results = compiler.execute_sql(chunked_fetch=self.chunked_fetch, chunk_size=self.chunk_size)
  File "/usr/local/lib/python3.8/site-packages/django/db/models/sql/compiler.py", line 1151, in execute_sql
    cursor.execute(sql, params)
  File "/usr/local/lib/python3.8/site-packages/django/db/backends/utils.py", line 100, in execute
    return super().execute(sql, params)
  File "/usr/local/lib/python3.8/site-packages/django/db/backends/utils.py", line 68, in execute
    return self._execute_with_wrappers(sql, params, many=False, executor=self._execute)
  File "/usr/local/lib/python3.8/site-packages/django/db/backends/utils.py", line 77, in _execute_with_wrappers
    return executor(sql, params, many, context)
  File "/usr/local/lib/python3.8/site-packages/django/db/backends/utils.py", line 86, in _execute
    return self.cursor.execute(sql, params)
  File "/usr/local/lib/python3.8/site-packages/django/db/utils.py", line 90, in __exit__
    raise dj_exc_value.with_traceback(traceback) from exc_value
  File "/usr/local/lib/python3.8/site-packages/django/db/backends/utils.py", line 86, in _execute
    return self.cursor.execute(sql, params)
django.db.utils.ProgrammingError: relation "jobs_job" does not exist
LINE 1: ...t", "jobs_job"."filled", "jobs_job"."salary" FROM "jobs_job"...
                                                             ^

Internal Server Error: /
Traceback (most recent call last):
  File "/usr/local/lib/python3.8/site-packages/django/db/backends/utils.py", line 86, in _execute
    return self.cursor.execute(sql, params)
psycopg2.errors.UndefinedTable: relation "jobs_job" does not exist
LINE 1: ...t", "jobs_job"."filled", "jobs_job"."salary" FROM "jobs_job"...
                                                             ^


The above exception was the direct cause of the following exception:

Traceback (most recent call last):
  File "/usr/local/lib/python3.8/site-packages/django/core/handlers/exception.py", line 34, in inner
    response = get_response(request)
  File "/usr/local/lib/python3.8/site-packages/django/core/handlers/base.py", line 145, in _get_response
    response = self.process_exception_by_middleware(e, request)
  File "/usr/local/lib/python3.8/site-packages/django/core/handlers/base.py", line 143, in _get_response
    response = response.render()
  File "/usr/local/lib/python3.8/site-packages/django/template/response.py", line 105, in render
    self.content = self.rendered_content
  File "/usr/local/lib/python3.8/site-packages/django/template/response.py", line 83, in rendered_content
    return template.render(context, self._request)
  File "/usr/local/lib/python3.8/site-packages/django/template/backends/django.py", line 61, in render
    return self.template.render(context)
  File "/usr/local/lib/python3.8/site-packages/django/template/base.py", line 171, in render
    return self._render(context)
  File "/usr/local/lib/python3.8/site-packages/django/template/base.py", line 163, in _render
    return self.nodelist.render(context)
  File "/usr/local/lib/python3.8/site-packages/django/template/base.py", line 936, in render
    bit = node.render_annotated(context)
  File "/usr/local/lib/python3.8/site-packages/django/template/base.py", line 903, in render_annotated
    return self.render(context)
  File "/usr/local/lib/python3.8/site-packages/django/template/loader_tags.py", line 150, in render
    return compiled_parent._render(context)
  File "/usr/local/lib/python3.8/site-packages/django/template/base.py", line 163, in _render
    return self.nodelist.render(context)
  File "/usr/local/lib/python3.8/site-packages/django/template/base.py", line 936, in render
    bit = node.render_annotated(context)
  File "/usr/local/lib/python3.8/site-packages/django/template/base.py", line 903, in render_annotated
    return self.render(context)
  File "/usr/local/lib/python3.8/site-packages/django/template/loader_tags.py", line 62, in render
    result = block.nodelist.render(context)
  File "/usr/local/lib/python3.8/site-packages/django/template/base.py", line 936, in render
    bit = node.render_annotated(context)
  File "/usr/local/lib/python3.8/site-packages/django/template/base.py", line 903, in render_annotated
    return self.render(context)
  File "/usr/local/lib/python3.8/site-packages/django/template/defaulttags.py", line 166, in render
    len_values = len(values)
  File "/usr/local/lib/python3.8/site-packages/django/db/models/query.py", line 258, in __len__
    self._fetch_all()
  File "/usr/local/lib/python3.8/site-packages/django/db/models/query.py", line 1261, in _fetch_all
    self._result_cache = list(self._iterable_class(self))
  File "/usr/local/lib/python3.8/site-packages/django/db/models/query.py", line 57, in __iter__
    results = compiler.execute_sql(chunked_fetch=self.chunked_fetch, chunk_size=self.chunk_size)
  File "/usr/local/lib/python3.8/site-packages/django/db/models/sql/compiler.py", line 1151, in execute_sql
    cursor.execute(sql, params)
  File "/usr/local/lib/python3.8/site-packages/django/db/backends/utils.py", line 100, in execute
    return super().execute(sql, params)
  File "/usr/local/lib/python3.8/site-packages/django/db/backends/utils.py", line 68, in execute
    return self._execute_with_wrappers(sql, params, many=False, executor=self._execute)
  File "/usr/local/lib/python3.8/site-packages/django/db/backends/utils.py", line 77, in _execute_with_wrappers
    return executor(sql, params, many, context)
  File "/usr/local/lib/python3.8/site-packages/django/db/backends/utils.py", line 86, in _execute
    return self.cursor.execute(sql, params)
  File "/usr/local/lib/python3.8/site-packages/django/db/utils.py", line 90, in __exit__
    raise dj_exc_value.with_traceback(traceback) from exc_value
  File "/usr/local/lib/python3.8/site-packages/django/db/backends/utils.py", line 86, in _execute
    return self.cursor.execute(sql, params)
django.db.utils.ProgrammingError: relation "jobs_job" does not exist
LINE 1: ...t", "jobs_job"."filled", "jobs_job"."salary" FROM "jobs_job"...
                                                             ^

"GET / HTTP/1.1" 500 207644
"GET / HTTP/1.1" 500 207644
Internal Server Error: /
Traceback (most recent call last):
  File "/usr/local/lib/python3.8/site-packages/django/db/backends/utils.py", line 86, in _execute
    return self.cursor.execute(sql, params)
psycopg2.errors.UndefinedTable: relation "jobs_job" does not exist
LINE 1: ...t", "jobs_job"."filled", "jobs_job"."salary" FROM "jobs_job"...
                                                             ^


The above exception was the direct cause of the following exception:

Traceback (most recent call last):
  File "/usr/local/lib/python3.8/site-packages/django/core/handlers/exception.py", line 34, in inner
    response = get_response(request)
  File "/usr/local/lib/python3.8/site-packages/django/core/handlers/base.py", line 145, in _get_response
    response = self.process_exception_by_middleware(e, request)
  File "/usr/local/lib/python3.8/site-packages/django/core/handlers/base.py", line 143, in _get_response
    response = response.render()
  File "/usr/local/lib/python3.8/site-packages/django/template/response.py", line 105, in render
    self.content = self.rendered_content
  File "/usr/local/lib/python3.8/site-packages/django/template/response.py", line 83, in rendered_content
    return template.render(context, self._request)
  File "/usr/local/lib/python3.8/site-packages/django/template/backends/django.py", line 61, in render
    return self.template.render(context)
  File "/usr/local/lib/python3.8/site-packages/django/template/base.py", line 171, in render
    return self._render(context)
  File "/usr/local/lib/python3.8/site-packages/django/template/base.py", line 163, in _render
    return self.nodelist.render(context)
  File "/usr/local/lib/python3.8/site-packages/django/template/base.py", line 936, in render
    bit = node.render_annotated(context)
  File "/usr/local/lib/python3.8/site-packages/django/template/base.py", line 903, in render_annotated
    return self.render(context)
  File "/usr/local/lib/python3.8/site-packages/django/template/loader_tags.py", line 150, in render
    return compiled_parent._render(context)
  File "/usr/local/lib/python3.8/site-packages/django/template/base.py", line 163, in _render
    return self.nodelist.render(context)
  File "/usr/local/lib/python3.8/site-packages/django/template/base.py", line 936, in render
    bit = node.render_annotated(context)
  File "/usr/local/lib/python3.8/site-packages/django/template/base.py", line 903, in render_annotated
    return self.render(context)
  File "/usr/local/lib/python3.8/site-packages/django/template/loader_tags.py", line 62, in render
    result = block.nodelist.render(context)
  File "/usr/local/lib/python3.8/site-packages/django/template/base.py", line 936, in render
    bit = node.render_annotated(context)
  File "/usr/local/lib/python3.8/site-packages/django/template/base.py", line 903, in render_annotated
    return self.render(context)
  File "/usr/local/lib/python3.8/site-packages/django/template/defaulttags.py", line 166, in render
    len_values = len(values)
  File "/usr/local/lib/python3.8/site-packages/django/db/models/query.py", line 258, in __len__
    self._fetch_all()
  File "/usr/local/lib/python3.8/site-packages/django/db/models/query.py", line 1261, in _fetch_all
    self._result_cache = list(self._iterable_class(self))
  File "/usr/local/lib/python3.8/site-packages/django/db/models/query.py", line 57, in __iter__
    results = compiler.execute_sql(chunked_fetch=self.chunked_fetch, chunk_size=self.chunk_size)
  File "/usr/local/lib/python3.8/site-packages/django/db/models/sql/compiler.py", line 1151, in execute_sql
    cursor.execute(sql, params)
  File "/usr/local/lib/python3.8/site-packages/django/db/backends/utils.py", line 100, in execute
    return super().execute(sql, params)
  File "/usr/local/lib/python3.8/site-packages/django/db/backends/utils.py", line 68, in execute
    return self._execute_with_wrappers(sql, params, many=False, executor=self._execute)
  File "/usr/local/lib/python3.8/site-packages/django/db/backends/utils.py", line 77, in _execute_with_wrappers
    return executor(sql, params, many, context)
  File "/usr/local/lib/python3.8/site-packages/django/db/backends/utils.py", line 86, in _execute
    return self.cursor.execute(sql, params)
  File "/usr/local/lib/python3.8/site-packages/django/db/utils.py", line 90, in __exit__
    raise dj_exc_value.with_traceback(traceback) from exc_value
  File "/usr/local/lib/python3.8/site-packages/django/db/backends/utils.py", line 86, in _execute
    return self.cursor.execute(sql, params)
django.db.utils.ProgrammingError: relation "jobs_job" does not exist
LINE 1: ...t", "jobs_job"."filled", "jobs_job"."salary" FROM "jobs_job"...
                                                             ^

Internal Server Error: /
Traceback (most recent call last):
  File "/usr/local/lib/python3.8/site-packages/django/db/backends/utils.py", line 86, in _execute
    return self.cursor.execute(sql, params)
psycopg2.errors.UndefinedTable: relation "jobs_job" does not exist
LINE 1: ...t", "jobs_job"."filled", "jobs_job"."salary" FROM "jobs_job"...
                                                             ^


The above exception was the direct cause of the following exception:

Traceback (most recent call last):
  File "/usr/local/lib/python3.8/site-packages/django/core/handlers/exception.py", line 34, in inner
    response = get_response(request)
  File "/usr/local/lib/python3.8/site-packages/django/core/handlers/base.py", line 145, in _get_response
    response = self.process_exception_by_middleware(e, request)
  File "/usr/local/lib/python3.8/site-packages/django/core/handlers/base.py", line 143, in _get_response
    response = response.render()
  File "/usr/local/lib/python3.8/site-packages/django/template/response.py", line 105, in render
    self.content = self.rendered_content
  File "/usr/local/lib/python3.8/site-packages/django/template/response.py", line 83, in rendered_content
    return template.render(context, self._request)
  File "/usr/local/lib/python3.8/site-packages/django/template/backends/django.py", line 61, in render
    return self.template.render(context)
  File "/usr/local/lib/python3.8/site-packages/django/template/base.py", line 171, in render
    return self._render(context)
  File "/usr/local/lib/python3.8/site-packages/django/template/base.py", line 163, in _render
    return self.nodelist.render(context)
  File "/usr/local/lib/python3.8/site-packages/django/template/base.py", line 936, in render
    bit = node.render_annotated(context)
  File "/usr/local/lib/python3.8/site-packages/django/template/base.py", line 903, in render_annotated
    return self.render(context)
  File "/usr/local/lib/python3.8/site-packages/django/template/loader_tags.py", line 150, in render
    return compiled_parent._render(context)
  File "/usr/local/lib/python3.8/site-packages/django/template/base.py", line 163, in _render
    return self.nodelist.render(context)
  File "/usr/local/lib/python3.8/site-packages/django/template/base.py", line 936, in render
    bit = node.render_annotated(context)
  File "/usr/local/lib/python3.8/site-packages/django/template/base.py", line 903, in render_annotated
    return self.render(context)
  File "/usr/local/lib/python3.8/site-packages/django/template/loader_tags.py", line 62, in render
    result = block.nodelist.render(context)
  File "/usr/local/lib/python3.8/site-packages/django/template/base.py", line 936, in render
    bit = node.render_annotated(context)
  File "/usr/local/lib/python3.8/site-packages/django/template/base.py", line 903, in render_annotated
    return self.render(context)
  File "/usr/local/lib/python3.8/site-packages/django/template/defaulttags.py", line 166, in render
    len_values = len(values)
  File "/usr/local/lib/python3.8/site-packages/django/db/models/query.py", line 258, in __len__
    self._fetch_all()
  File "/usr/local/lib/python3.8/site-packages/django/db/models/query.py", line 1261, in _fetch_all
    self._result_cache = list(self._iterable_class(self))
  File "/usr/local/lib/python3.8/site-packages/django/db/models/query.py", line 57, in __iter__
    results = compiler.execute_sql(chunked_fetch=self.chunked_fetch, chunk_size=self.chunk_size)
  File "/usr/local/lib/python3.8/site-packages/django/db/models/sql/compiler.py", line 1151, in execute_sql
    cursor.execute(sql, params)
  File "/usr/local/lib/python3.8/site-packages/django/db/backends/utils.py", line 100, in execute
    return super().execute(sql, params)
  File "/usr/local/lib/python3.8/site-packages/django/db/backends/utils.py", line 68, in execute
    return self._execute_with_wrappers(sql, params, many=False, executor=self._execute)
  File "/usr/local/lib/python3.8/site-packages/django/db/backends/utils.py", line 77, in _execute_with_wrappers
    return executor(sql, params, many, context)
  File "/usr/local/lib/python3.8/site-packages/django/db/backends/utils.py", line 86, in _execute
    return self.cursor.execute(sql, params)
  File "/usr/local/lib/python3.8/site-packages/django/db/utils.py", line 90, in __exit__
    raise dj_exc_value.with_traceback(traceback) from exc_value
  File "/usr/local/lib/python3.8/site-packages/django/db/backends/utils.py", line 86, in _execute
    return self.cursor.execute(sql, params)
django.db.utils.ProgrammingError: relation "jobs_job" does not exist
LINE 1: ...t", "jobs_job"."filled", "jobs_job"."salary" FROM "jobs_job"...
                                                             ^

"GET / HTTP/1.1" 500 207781
"GET / HTTP/1.1" 500 207781
Internal Server Error: /
Traceback (most recent call last):
  File "/usr/local/lib/python3.8/site-packages/django/db/backends/utils.py", line 86, in _execute
    return self.cursor.execute(sql, params)
psycopg2.errors.UndefinedTable: relation "jobs_job" does not exist
LINE 1: ...t", "jobs_job"."filled", "jobs_job"."salary" FROM "jobs_job"...
                                                             ^


The above exception was the direct cause of the following exception:

Traceback (most recent call last):
  File "/usr/local/lib/python3.8/site-packages/django/core/handlers/exception.py", line 34, in inner
    response = get_response(request)
  File "/usr/local/lib/python3.8/site-packages/django/core/handlers/base.py", line 145, in _get_response
    response = self.process_exception_by_middleware(e, request)
  File "/usr/local/lib/python3.8/site-packages/django/core/handlers/base.py", line 143, in _get_response
    response = response.render()
  File "/usr/local/lib/python3.8/site-packages/django/template/response.py", line 105, in render
    self.content = self.rendered_content
  File "/usr/local/lib/python3.8/site-packages/django/template/response.py", line 83, in rendered_content
    return template.render(context, self._request)
  File "/usr/local/lib/python3.8/site-packages/django/template/backends/django.py", line 61, in render
    return self.template.render(context)
  File "/usr/local/lib/python3.8/site-packages/django/template/base.py", line 171, in render
    return self._render(context)
  File "/usr/local/lib/python3.8/site-packages/django/template/base.py", line 163, in _render
    return self.nodelist.render(context)
  File "/usr/local/lib/python3.8/site-packages/django/template/base.py", line 936, in render
    bit = node.render_annotated(context)
  File "/usr/local/lib/python3.8/site-packages/django/template/base.py", line 903, in render_annotated
    return self.render(context)
  File "/usr/local/lib/python3.8/site-packages/django/template/loader_tags.py", line 150, in render
    return compiled_parent._render(context)
  File "/usr/local/lib/python3.8/site-packages/django/template/base.py", line 163, in _render
    return self.nodelist.render(context)
  File "/usr/local/lib/python3.8/site-packages/django/template/base.py", line 936, in render
    bit = node.render_annotated(context)
  File "/usr/local/lib/python3.8/site-packages/django/template/base.py", line 903, in render_annotated
    return self.render(context)
  File "/usr/local/lib/python3.8/site-packages/django/template/loader_tags.py", line 62, in render
    result = block.nodelist.render(context)
  File "/usr/local/lib/python3.8/site-packages/django/template/base.py", line 936, in render
    bit = node.render_annotated(context)
  File "/usr/local/lib/python3.8/site-packages/django/template/base.py", line 903, in render_annotated
    return self.render(context)
  File "/usr/local/lib/python3.8/site-packages/django/template/defaulttags.py", line 166, in render
    len_values = len(values)
  File "/usr/local/lib/python3.8/site-packages/django/db/models/query.py", line 258, in __len__
    self._fetch_all()
  File "/usr/local/lib/python3.8/site-packages/django/db/models/query.py", line 1261, in _fetch_all
    self._result_cache = list(self._iterable_class(self))
  File "/usr/local/lib/python3.8/site-packages/django/db/models/query.py", line 57, in __iter__
    results = compiler.execute_sql(chunked_fetch=self.chunked_fetch, chunk_size=self.chunk_size)
  File "/usr/local/lib/python3.8/site-packages/django/db/models/sql/compiler.py", line 1151, in execute_sql
    cursor.execute(sql, params)
  File "/usr/local/lib/python3.8/site-packages/django/db/backends/utils.py", line 100, in execute
    return super().execute(sql, params)
  File "/usr/local/lib/python3.8/site-packages/django/db/backends/utils.py", line 68, in execute
    return self._execute_with_wrappers(sql, params, many=False, executor=self._execute)
  File "/usr/local/lib/python3.8/site-packages/django/db/backends/utils.py", line 77, in _execute_with_wrappers
    return executor(sql, params, many, context)
  File "/usr/local/lib/python3.8/site-packages/django/db/backends/utils.py", line 86, in _execute
    return self.cursor.execute(sql, params)
  File "/usr/local/lib/python3.8/site-packages/django/db/utils.py", line 90, in __exit__
    raise dj_exc_value.with_traceback(traceback) from exc_value
  File "/usr/local/lib/python3.8/site-packages/django/db/backends/utils.py", line 86, in _execute
    return self.cursor.execute(sql, params)
django.db.utils.ProgrammingError: relation "jobs_job" does not exist
LINE 1: ...t", "jobs_job"."filled", "jobs_job"."salary" FROM "jobs_job"...
                                                             ^

Internal Server Error: /
Traceback (most recent call last):
  File "/usr/local/lib/python3.8/site-packages/django/db/backends/utils.py", line 86, in _execute
    return self.cursor.execute(sql, params)
psycopg2.errors.UndefinedTable: relation "jobs_job" does not exist
LINE 1: ...t", "jobs_job"."filled", "jobs_job"."salary" FROM "jobs_job"...
                                                             ^


The above exception was the direct cause of the following exception:

Traceback (most recent call last):
  File "/usr/local/lib/python3.8/site-packages/django/core/handlers/exception.py", line 34, in inner
    response = get_response(request)
  File "/usr/local/lib/python3.8/site-packages/django/core/handlers/base.py", line 145, in _get_response
    response = self.process_exception_by_middleware(e, request)
  File "/usr/local/lib/python3.8/site-packages/django/core/handlers/base.py", line 143, in _get_response
    response = response.render()
  File "/usr/local/lib/python3.8/site-packages/django/template/response.py", line 105, in render
    self.content = self.rendered_content
  File "/usr/local/lib/python3.8/site-packages/django/template/response.py", line 83, in rendered_content
    return template.render(context, self._request)
  File "/usr/local/lib/python3.8/site-packages/django/template/backends/django.py", line 61, in render
    return self.template.render(context)
  File "/usr/local/lib/python3.8/site-packages/django/template/base.py", line 171, in render
    return self._render(context)
  File "/usr/local/lib/python3.8/site-packages/django/template/base.py", line 163, in _render
    return self.nodelist.render(context)
  File "/usr/local/lib/python3.8/site-packages/django/template/base.py", line 936, in render
    bit = node.render_annotated(context)
  File "/usr/local/lib/python3.8/site-packages/django/template/base.py", line 903, in render_annotated
    return self.render(context)
  File "/usr/local/lib/python3.8/site-packages/django/template/loader_tags.py", line 150, in render
    return compiled_parent._render(context)
  File "/usr/local/lib/python3.8/site-packages/django/template/base.py", line 163, in _render
    return self.nodelist.render(context)
  File "/usr/local/lib/python3.8/site-packages/django/template/base.py", line 936, in render
    bit = node.render_annotated(context)
  File "/usr/local/lib/python3.8/site-packages/django/template/base.py", line 903, in render_annotated
    return self.render(context)
  File "/usr/local/lib/python3.8/site-packages/django/template/loader_tags.py", line 62, in render
    result = block.nodelist.render(context)
  File "/usr/local/lib/python3.8/site-packages/django/template/base.py", line 936, in render
    bit = node.render_annotated(context)
  File "/usr/local/lib/python3.8/site-packages/django/template/base.py", line 903, in render_annotated
    return self.render(context)
  File "/usr/local/lib/python3.8/site-packages/django/template/defaulttags.py", line 166, in render
    len_values = len(values)
  File "/usr/local/lib/python3.8/site-packages/django/db/models/query.py", line 258, in __len__
    self._fetch_all()
  File "/usr/local/lib/python3.8/site-packages/django/db/models/query.py", line 1261, in _fetch_all
    self._result_cache = list(self._iterable_class(self))
  File "/usr/local/lib/python3.8/site-packages/django/db/models/query.py", line 57, in __iter__
    results = compiler.execute_sql(chunked_fetch=self.chunked_fetch, chunk_size=self.chunk_size)
  File "/usr/local/lib/python3.8/site-packages/django/db/models/sql/compiler.py", line 1151, in execute_sql
    cursor.execute(sql, params)
  File "/usr/local/lib/python3.8/site-packages/django/db/backends/utils.py", line 100, in execute
    return super().execute(sql, params)
  File "/usr/local/lib/python3.8/site-packages/django/db/backends/utils.py", line 68, in execute
    return self._execute_with_wrappers(sql, params, many=False, executor=self._execute)
  File "/usr/local/lib/python3.8/site-packages/django/db/backends/utils.py", line 77, in _execute_with_wrappers
    return executor(sql, params, many, context)
  File "/usr/local/lib/python3.8/site-packages/django/db/backends/utils.py", line 86, in _execute
    return self.cursor.execute(sql, params)
  File "/usr/local/lib/python3.8/site-packages/django/db/utils.py", line 90, in __exit__
    raise dj_exc_value.with_traceback(traceback) from exc_value
  File "/usr/local/lib/python3.8/site-packages/django/db/backends/utils.py", line 86, in _execute
    return self.cursor.execute(sql, params)
django.db.utils.ProgrammingError: relation "jobs_job" does not exist
LINE 1: ...t", "jobs_job"."filled", "jobs_job"."salary" FROM "jobs_job"...
                                                             ^

"GET / HTTP/1.1" 500 207644
"GET / HTTP/1.1" 500 207644
"GET /admin/ HTTP/1.1" 302 0
"GET /admin/ HTTP/1.1" 302 0
"GET /admin/login/?next=/admin/ HTTP/1.1" 200 1918
"GET /admin/login/?next=/admin/ HTTP/1.1" 200 1918
Internal Server Error: /admin/login/
Traceback (most recent call last):
  File "/usr/local/lib/python3.8/site-packages/django/db/backends/utils.py", line 86, in _execute
    return self.cursor.execute(sql, params)
psycopg2.errors.UndefinedTable: relation "accounts_user" does not exist
LINE 1: ...s_user"."admin", "accounts_user"."timestamp" FROM "accounts_...
                                                             ^


The above exception was the direct cause of the following exception:

Traceback (most recent call last):
  File "/usr/local/lib/python3.8/site-packages/django/core/handlers/exception.py", line 34, in inner
    response = get_response(request)
  File "/usr/local/lib/python3.8/site-packages/django/core/handlers/base.py", line 115, in _get_response
    response = self.process_exception_by_middleware(e, request)
  File "/usr/local/lib/python3.8/site-packages/django/core/handlers/base.py", line 113, in _get_response
    response = wrapped_callback(request, *callback_args, **callback_kwargs)
  File "/usr/local/lib/python3.8/site-packages/django/views/decorators/cache.py", line 44, in _wrapped_view_func
    response = view_func(request, *args, **kwargs)
  File "/usr/local/lib/python3.8/site-packages/django/contrib/admin/sites.py", line 407, in login
    return LoginView.as_view(**defaults)(request)
  File "/usr/local/lib/python3.8/site-packages/django/views/generic/base.py", line 71, in view
    return self.dispatch(request, *args, **kwargs)
  File "/usr/local/lib/python3.8/site-packages/django/utils/decorators.py", line 43, in _wrapper
    return bound_method(*args, **kwargs)
  File "/usr/local/lib/python3.8/site-packages/django/views/decorators/debug.py", line 76, in sensitive_post_parameters_wrapper
    return view(request, *args, **kwargs)
  File "/usr/local/lib/python3.8/site-packages/django/utils/decorators.py", line 43, in _wrapper
    return bound_method(*args, **kwargs)
  File "/usr/local/lib/python3.8/site-packages/django/utils/decorators.py", line 130, in _wrapped_view
    response = view_func(request, *args, **kwargs)
  File "/usr/local/lib/python3.8/site-packages/django/utils/decorators.py", line 43, in _wrapper
    return bound_method(*args, **kwargs)
  File "/usr/local/lib/python3.8/site-packages/django/views/decorators/cache.py", line 44, in _wrapped_view_func
    response = view_func(request, *args, **kwargs)
  File "/usr/local/lib/python3.8/site-packages/django/contrib/auth/views.py", line 63, in dispatch
    return super().dispatch(request, *args, **kwargs)
  File "/usr/local/lib/python3.8/site-packages/django/views/generic/base.py", line 97, in dispatch
    return handler(request, *args, **kwargs)
  File "/usr/local/lib/python3.8/site-packages/django/views/generic/edit.py", line 141, in post
    if form.is_valid():
  File "/usr/local/lib/python3.8/site-packages/django/forms/forms.py", line 180, in is_valid
    return self.is_bound and not self.errors
  File "/usr/local/lib/python3.8/site-packages/django/forms/forms.py", line 175, in errors
    self.full_clean()
  File "/usr/local/lib/python3.8/site-packages/django/forms/forms.py", line 377, in full_clean
    self._clean_form()
  File "/usr/local/lib/python3.8/site-packages/django/forms/forms.py", line 404, in _clean_form
    cleaned_data = self.clean()
  File "/usr/local/lib/python3.8/site-packages/django/contrib/auth/forms.py", line 214, in clean
    self.user_cache = authenticate(self.request, username=username, password=password)
  File "/usr/local/lib/python3.8/site-packages/django/contrib/auth/__init__.py", line 72, in authenticate
    user = backend.authenticate(request, **credentials)
  File "/usr/local/lib/python3.8/site-packages/django/contrib/auth/backends.py", line 46, in authenticate
    user = UserModel._default_manager.get_by_natural_key(username)
  File "/usr/local/lib/python3.8/site-packages/django/contrib/auth/base_user.py", line 44, in get_by_natural_key
    return self.get(**{self.model.USERNAME_FIELD: username})
  File "/usr/local/lib/python3.8/site-packages/django/db/models/manager.py", line 82, in manager_method
    return getattr(self.get_queryset(), name)(*args, **kwargs)
  File "/usr/local/lib/python3.8/site-packages/django/db/models/query.py", line 411, in get
    num = len(clone)
  File "/usr/local/lib/python3.8/site-packages/django/db/models/query.py", line 258, in __len__
    self._fetch_all()
  File "/usr/local/lib/python3.8/site-packages/django/db/models/query.py", line 1261, in _fetch_all
    self._result_cache = list(self._iterable_class(self))
  File "/usr/local/lib/python3.8/site-packages/django/db/models/query.py", line 57, in __iter__
    results = compiler.execute_sql(chunked_fetch=self.chunked_fetch, chunk_size=self.chunk_size)
  File "/usr/local/lib/python3.8/site-packages/django/db/models/sql/compiler.py", line 1151, in execute_sql
    cursor.execute(sql, params)
  File "/usr/local/lib/python3.8/site-packages/django/db/backends/utils.py", line 100, in execute
    return super().execute(sql, params)
  File "/usr/local/lib/python3.8/site-packages/django/db/backends/utils.py", line 68, in execute
    return self._execute_with_wrappers(sql, params, many=False, executor=self._execute)
  File "/usr/local/lib/python3.8/site-packages/django/db/backends/utils.py", line 77, in _execute_with_wrappers
    return executor(sql, params, many, context)
  File "/usr/local/lib/python3.8/site-packages/django/db/backends/utils.py", line 86, in _execute
    return self.cursor.execute(sql, params)
  File "/usr/local/lib/python3.8/site-packages/django/db/utils.py", line 90, in __exit__
    raise dj_exc_value.with_traceback(traceback) from exc_value
  File "/usr/local/lib/python3.8/site-packages/django/db/backends/utils.py", line 86, in _execute
    return self.cursor.execute(sql, params)
django.db.utils.ProgrammingError: relation "accounts_user" does not exist
LINE 1: ...s_user"."admin", "accounts_user"."timestamp" FROM "accounts_...
                                                             ^

Internal Server Error: /admin/login/
Traceback (most recent call last):
  File "/usr/local/lib/python3.8/site-packages/django/db/backends/utils.py", line 86, in _execute
    return self.cursor.execute(sql, params)
psycopg2.errors.UndefinedTable: relation "accounts_user" does not exist
LINE 1: ...s_user"."admin", "accounts_user"."timestamp" FROM "accounts_...
                                                             ^


The above exception was the direct cause of the following exception:

Traceback (most recent call last):
  File "/usr/local/lib/python3.8/site-packages/django/core/handlers/exception.py", line 34, in inner
    response = get_response(request)
  File "/usr/local/lib/python3.8/site-packages/django/core/handlers/base.py", line 115, in _get_response
    response = self.process_exception_by_middleware(e, request)
  File "/usr/local/lib/python3.8/site-packages/django/core/handlers/base.py", line 113, in _get_response
    response = wrapped_callback(request, *callback_args, **callback_kwargs)
  File "/usr/local/lib/python3.8/site-packages/django/views/decorators/cache.py", line 44, in _wrapped_view_func
    response = view_func(request, *args, **kwargs)
  File "/usr/local/lib/python3.8/site-packages/django/contrib/admin/sites.py", line 407, in login
    return LoginView.as_view(**defaults)(request)
  File "/usr/local/lib/python3.8/site-packages/django/views/generic/base.py", line 71, in view
    return self.dispatch(request, *args, **kwargs)
  File "/usr/local/lib/python3.8/site-packages/django/utils/decorators.py", line 43, in _wrapper
    return bound_method(*args, **kwargs)
  File "/usr/local/lib/python3.8/site-packages/django/views/decorators/debug.py", line 76, in sensitive_post_parameters_wrapper
    return view(request, *args, **kwargs)
  File "/usr/local/lib/python3.8/site-packages/django/utils/decorators.py", line 43, in _wrapper
    return bound_method(*args, **kwargs)
  File "/usr/local/lib/python3.8/site-packages/django/utils/decorators.py", line 130, in _wrapped_view
    response = view_func(request, *args, **kwargs)
  File "/usr/local/lib/python3.8/site-packages/django/utils/decorators.py", line 43, in _wrapper
    return bound_method(*args, **kwargs)
  File "/usr/local/lib/python3.8/site-packages/django/views/decorators/cache.py", line 44, in _wrapped_view_func
    response = view_func(request, *args, **kwargs)
  File "/usr/local/lib/python3.8/site-packages/django/contrib/auth/views.py", line 63, in dispatch
    return super().dispatch(request, *args, **kwargs)
  File "/usr/local/lib/python3.8/site-packages/django/views/generic/base.py", line 97, in dispatch
    return handler(request, *args, **kwargs)
  File "/usr/local/lib/python3.8/site-packages/django/views/generic/edit.py", line 141, in post
    if form.is_valid():
  File "/usr/local/lib/python3.8/site-packages/django/forms/forms.py", line 180, in is_valid
    return self.is_bound and not self.errors
  File "/usr/local/lib/python3.8/site-packages/django/forms/forms.py", line 175, in errors
    self.full_clean()
  File "/usr/local/lib/python3.8/site-packages/django/forms/forms.py", line 377, in full_clean
    self._clean_form()
  File "/usr/local/lib/python3.8/site-packages/django/forms/forms.py", line 404, in _clean_form
    cleaned_data = self.clean()
  File "/usr/local/lib/python3.8/site-packages/django/contrib/auth/forms.py", line 214, in clean
    self.user_cache = authenticate(self.request, username=username, password=password)
  File "/usr/local/lib/python3.8/site-packages/django/contrib/auth/__init__.py", line 72, in authenticate
    user = backend.authenticate(request, **credentials)
  File "/usr/local/lib/python3.8/site-packages/django/contrib/auth/backends.py", line 46, in authenticate
    user = UserModel._default_manager.get_by_natural_key(username)
  File "/usr/local/lib/python3.8/site-packages/django/contrib/auth/base_user.py", line 44, in get_by_natural_key
    return self.get(**{self.model.USERNAME_FIELD: username})
  File "/usr/local/lib/python3.8/site-packages/django/db/models/manager.py", line 82, in manager_method
    return getattr(self.get_queryset(), name)(*args, **kwargs)
  File "/usr/local/lib/python3.8/site-packages/django/db/models/query.py", line 411, in get
    num = len(clone)
  File "/usr/local/lib/python3.8/site-packages/django/db/models/query.py", line 258, in __len__
    self._fetch_all()
  File "/usr/local/lib/python3.8/site-packages/django/db/models/query.py", line 1261, in _fetch_all
    self._result_cache = list(self._iterable_class(self))
  File "/usr/local/lib/python3.8/site-packages/django/db/models/query.py", line 57, in __iter__
    results = compiler.execute_sql(chunked_fetch=self.chunked_fetch, chunk_size=self.chunk_size)
  File "/usr/local/lib/python3.8/site-packages/django/db/models/sql/compiler.py", line 1151, in execute_sql
    cursor.execute(sql, params)
  File "/usr/local/lib/python3.8/site-packages/django/db/backends/utils.py", line 100, in execute
    return super().execute(sql, params)
  File "/usr/local/lib/python3.8/site-packages/django/db/backends/utils.py", line 68, in execute
    return self._execute_with_wrappers(sql, params, many=False, executor=self._execute)
  File "/usr/local/lib/python3.8/site-packages/django/db/backends/utils.py", line 77, in _execute_with_wrappers
    return executor(sql, params, many, context)
  File "/usr/local/lib/python3.8/site-packages/django/db/backends/utils.py", line 86, in _execute
    return self.cursor.execute(sql, params)
  File "/usr/local/lib/python3.8/site-packages/django/db/utils.py", line 90, in __exit__
    raise dj_exc_value.with_traceback(traceback) from exc_value
  File "/usr/local/lib/python3.8/site-packages/django/db/backends/utils.py", line 86, in _execute
    return self.cursor.execute(sql, params)
django.db.utils.ProgrammingError: relation "accounts_user" does not exist
LINE 1: ...s_user"."admin", "accounts_user"."timestamp" FROM "accounts_...
                                                             ^

"POST /admin/login/?next=/admin/ HTTP/1.1" 500 218305
"POST /admin/login/?next=/admin/ HTTP/1.1" 500 218305
Internal Server Error: /admin/login/
Traceback (most recent call last):
  File "/usr/local/lib/python3.8/site-packages/django/db/backends/utils.py", line 86, in _execute
    return self.cursor.execute(sql, params)
psycopg2.errors.UndefinedTable: relation "accounts_user" does not exist
LINE 1: ...s_user"."admin", "accounts_user"."timestamp" FROM "accounts_...
                                                             ^


The above exception was the direct cause of the following exception:

Traceback (most recent call last):
  File "/usr/local/lib/python3.8/site-packages/django/core/handlers/exception.py", line 34, in inner
    response = get_response(request)
  File "/usr/local/lib/python3.8/site-packages/django/core/handlers/base.py", line 115, in _get_response
    response = self.process_exception_by_middleware(e, request)
  File "/usr/local/lib/python3.8/site-packages/django/core/handlers/base.py", line 113, in _get_response
    response = wrapped_callback(request, *callback_args, **callback_kwargs)
  File "/usr/local/lib/python3.8/site-packages/django/views/decorators/cache.py", line 44, in _wrapped_view_func
    response = view_func(request, *args, **kwargs)
  File "/usr/local/lib/python3.8/site-packages/django/contrib/admin/sites.py", line 407, in login
    return LoginView.as_view(**defaults)(request)
  File "/usr/local/lib/python3.8/site-packages/django/views/generic/base.py", line 71, in view
    return self.dispatch(request, *args, **kwargs)
  File "/usr/local/lib/python3.8/site-packages/django/utils/decorators.py", line 43, in _wrapper
    return bound_method(*args, **kwargs)
  File "/usr/local/lib/python3.8/site-packages/django/views/decorators/debug.py", line 76, in sensitive_post_parameters_wrapper
    return view(request, *args, **kwargs)
  File "/usr/local/lib/python3.8/site-packages/django/utils/decorators.py", line 43, in _wrapper
    return bound_method(*args, **kwargs)
  File "/usr/local/lib/python3.8/site-packages/django/utils/decorators.py", line 130, in _wrapped_view
    response = view_func(request, *args, **kwargs)
  File "/usr/local/lib/python3.8/site-packages/django/utils/decorators.py", line 43, in _wrapper
    return bound_method(*args, **kwargs)
  File "/usr/local/lib/python3.8/site-packages/django/views/decorators/cache.py", line 44, in _wrapped_view_func
    response = view_func(request, *args, **kwargs)
  File "/usr/local/lib/python3.8/site-packages/django/contrib/auth/views.py", line 63, in dispatch
    return super().dispatch(request, *args, **kwargs)
  File "/usr/local/lib/python3.8/site-packages/django/views/generic/base.py", line 97, in dispatch
    return handler(request, *args, **kwargs)
  File "/usr/local/lib/python3.8/site-packages/django/views/generic/edit.py", line 141, in post
    if form.is_valid():
  File "/usr/local/lib/python3.8/site-packages/django/forms/forms.py", line 180, in is_valid
    return self.is_bound and not self.errors
  File "/usr/local/lib/python3.8/site-packages/django/forms/forms.py", line 175, in errors
    self.full_clean()
  File "/usr/local/lib/python3.8/site-packages/django/forms/forms.py", line 377, in full_clean
    self._clean_form()
  File "/usr/local/lib/python3.8/site-packages/django/forms/forms.py", line 404, in _clean_form
    cleaned_data = self.clean()
  File "/usr/local/lib/python3.8/site-packages/django/contrib/auth/forms.py", line 214, in clean
    self.user_cache = authenticate(self.request, username=username, password=password)
  File "/usr/local/lib/python3.8/site-packages/django/contrib/auth/__init__.py", line 72, in authenticate
    user = backend.authenticate(request, **credentials)
  File "/usr/local/lib/python3.8/site-packages/django/contrib/auth/backends.py", line 46, in authenticate
    user = UserModel._default_manager.get_by_natural_key(username)
  File "/usr/local/lib/python3.8/site-packages/django/contrib/auth/base_user.py", line 44, in get_by_natural_key
    return self.get(**{self.model.USERNAME_FIELD: username})
  File "/usr/local/lib/python3.8/site-packages/django/db/models/manager.py", line 82, in manager_method
    return getattr(self.get_queryset(), name)(*args, **kwargs)
  File "/usr/local/lib/python3.8/site-packages/django/db/models/query.py", line 411, in get
    num = len(clone)
  File "/usr/local/lib/python3.8/site-packages/django/db/models/query.py", line 258, in __len__
    self._fetch_all()
  File "/usr/local/lib/python3.8/site-packages/django/db/models/query.py", line 1261, in _fetch_all
    self._result_cache = list(self._iterable_class(self))
  File "/usr/local/lib/python3.8/site-packages/django/db/models/query.py", line 57, in __iter__
    results = compiler.execute_sql(chunked_fetch=self.chunked_fetch, chunk_size=self.chunk_size)
  File "/usr/local/lib/python3.8/site-packages/django/db/models/sql/compiler.py", line 1151, in execute_sql
    cursor.execute(sql, params)
  File "/usr/local/lib/python3.8/site-packages/django/db/backends/utils.py", line 100, in execute
    return super().execute(sql, params)
  File "/usr/local/lib/python3.8/site-packages/django/db/backends/utils.py", line 68, in execute
    return self._execute_with_wrappers(sql, params, many=False, executor=self._execute)
  File "/usr/local/lib/python3.8/site-packages/django/db/backends/utils.py", line 77, in _execute_with_wrappers
    return executor(sql, params, many, context)
  File "/usr/local/lib/python3.8/site-packages/django/db/backends/utils.py", line 86, in _execute
    return self.cursor.execute(sql, params)
  File "/usr/local/lib/python3.8/site-packages/django/db/utils.py", line 90, in __exit__
    raise dj_exc_value.with_traceback(traceback) from exc_value
  File "/usr/local/lib/python3.8/site-packages/django/db/backends/utils.py", line 86, in _execute
    return self.cursor.execute(sql, params)
django.db.utils.ProgrammingError: relation "accounts_user" does not exist
LINE 1: ...s_user"."admin", "accounts_user"."timestamp" FROM "accounts_...
                                                             ^

Internal Server Error: /admin/login/
Traceback (most recent call last):
  File "/usr/local/lib/python3.8/site-packages/django/db/backends/utils.py", line 86, in _execute
    return self.cursor.execute(sql, params)
psycopg2.errors.UndefinedTable: relation "accounts_user" does not exist
LINE 1: ...s_user"."admin", "accounts_user"."timestamp" FROM "accounts_...
                                                             ^


The above exception was the direct cause of the following exception:

Traceback (most recent call last):
  File "/usr/local/lib/python3.8/site-packages/django/core/handlers/exception.py", line 34, in inner
    response = get_response(request)
  File "/usr/local/lib/python3.8/site-packages/django/core/handlers/base.py", line 115, in _get_response
    response = self.process_exception_by_middleware(e, request)
  File "/usr/local/lib/python3.8/site-packages/django/core/handlers/base.py", line 113, in _get_response
    response = wrapped_callback(request, *callback_args, **callback_kwargs)
  File "/usr/local/lib/python3.8/site-packages/django/views/decorators/cache.py", line 44, in _wrapped_view_func
    response = view_func(request, *args, **kwargs)
  File "/usr/local/lib/python3.8/site-packages/django/contrib/admin/sites.py", line 407, in login
    return LoginView.as_view(**defaults)(request)
  File "/usr/local/lib/python3.8/site-packages/django/views/generic/base.py", line 71, in view
    return self.dispatch(request, *args, **kwargs)
  File "/usr/local/lib/python3.8/site-packages/django/utils/decorators.py", line 43, in _wrapper
    return bound_method(*args, **kwargs)
  File "/usr/local/lib/python3.8/site-packages/django/views/decorators/debug.py", line 76, in sensitive_post_parameters_wrapper
    return view(request, *args, **kwargs)
  File "/usr/local/lib/python3.8/site-packages/django/utils/decorators.py", line 43, in _wrapper
    return bound_method(*args, **kwargs)
  File "/usr/local/lib/python3.8/site-packages/django/utils/decorators.py", line 130, in _wrapped_view
    response = view_func(request, *args, **kwargs)
  File "/usr/local/lib/python3.8/site-packages/django/utils/decorators.py", line 43, in _wrapper
    return bound_method(*args, **kwargs)
  File "/usr/local/lib/python3.8/site-packages/django/views/decorators/cache.py", line 44, in _wrapped_view_func
    response = view_func(request, *args, **kwargs)
  File "/usr/local/lib/python3.8/site-packages/django/contrib/auth/views.py", line 63, in dispatch
    return super().dispatch(request, *args, **kwargs)
  File "/usr/local/lib/python3.8/site-packages/django/views/generic/base.py", line 97, in dispatch
    return handler(request, *args, **kwargs)
  File "/usr/local/lib/python3.8/site-packages/django/views/generic/edit.py", line 141, in post
    if form.is_valid():
  File "/usr/local/lib/python3.8/site-packages/django/forms/forms.py", line 180, in is_valid
    return self.is_bound and not self.errors
  File "/usr/local/lib/python3.8/site-packages/django/forms/forms.py", line 175, in errors
    self.full_clean()
  File "/usr/local/lib/python3.8/site-packages/django/forms/forms.py", line 377, in full_clean
    self._clean_form()
  File "/usr/local/lib/python3.8/site-packages/django/forms/forms.py", line 404, in _clean_form
    cleaned_data = self.clean()
  File "/usr/local/lib/python3.8/site-packages/django/contrib/auth/forms.py", line 214, in clean
    self.user_cache = authenticate(self.request, username=username, password=password)
  File "/usr/local/lib/python3.8/site-packages/django/contrib/auth/__init__.py", line 72, in authenticate
    user = backend.authenticate(request, **credentials)
  File "/usr/local/lib/python3.8/site-packages/django/contrib/auth/backends.py", line 46, in authenticate
    user = UserModel._default_manager.get_by_natural_key(username)
  File "/usr/local/lib/python3.8/site-packages/django/contrib/auth/base_user.py", line 44, in get_by_natural_key
    return self.get(**{self.model.USERNAME_FIELD: username})
  File "/usr/local/lib/python3.8/site-packages/django/db/models/manager.py", line 82, in manager_method
    return getattr(self.get_queryset(), name)(*args, **kwargs)
  File "/usr/local/lib/python3.8/site-packages/django/db/models/query.py", line 411, in get
    num = len(clone)
  File "/usr/local/lib/python3.8/site-packages/django/db/models/query.py", line 258, in __len__
    self._fetch_all()
  File "/usr/local/lib/python3.8/site-packages/django/db/models/query.py", line 1261, in _fetch_all
    self._result_cache = list(self._iterable_class(self))
  File "/usr/local/lib/python3.8/site-packages/django/db/models/query.py", line 57, in __iter__
    results = compiler.execute_sql(chunked_fetch=self.chunked_fetch, chunk_size=self.chunk_size)
  File "/usr/local/lib/python3.8/site-packages/django/db/models/sql/compiler.py", line 1151, in execute_sql
    cursor.execute(sql, params)
  File "/usr/local/lib/python3.8/site-packages/django/db/backends/utils.py", line 100, in execute
    return super().execute(sql, params)
  File "/usr/local/lib/python3.8/site-packages/django/db/backends/utils.py", line 68, in execute
    return self._execute_with_wrappers(sql, params, many=False, executor=self._execute)
  File "/usr/local/lib/python3.8/site-packages/django/db/backends/utils.py", line 77, in _execute_with_wrappers
    return executor(sql, params, many, context)
  File "/usr/local/lib/python3.8/site-packages/django/db/backends/utils.py", line 86, in _execute
    return self.cursor.execute(sql, params)
  File "/usr/local/lib/python3.8/site-packages/django/db/utils.py", line 90, in __exit__
    raise dj_exc_value.with_traceback(traceback) from exc_value
  File "/usr/local/lib/python3.8/site-packages/django/db/backends/utils.py", line 86, in _execute
    return self.cursor.execute(sql, params)
django.db.utils.ProgrammingError: relation "accounts_user" does not exist
LINE 1: ...s_user"."admin", "accounts_user"."timestamp" FROM "accounts_...
                                                             ^

"POST /admin/login/?next=/admin/ HTTP/1.1" 500 218305
"POST /admin/login/?next=/admin/ HTTP/1.1" 500 218305
Internal Server Error: /
Traceback (most recent call last):
  File "/usr/local/lib/python3.8/site-packages/django/db/backends/utils.py", line 86, in _execute
    return self.cursor.execute(sql, params)
psycopg2.errors.UndefinedTable: relation "jobs_job" does not exist
LINE 1: ...t", "jobs_job"."filled", "jobs_job"."salary" FROM "jobs_job"...
                                                             ^


The above exception was the direct cause of the following exception:

Traceback (most recent call last):
  File "/usr/local/lib/python3.8/site-packages/django/core/handlers/exception.py", line 34, in inner
    response = get_response(request)
  File "/usr/local/lib/python3.8/site-packages/django/core/handlers/base.py", line 145, in _get_response
    response = self.process_exception_by_middleware(e, request)
  File "/usr/local/lib/python3.8/site-packages/django/core/handlers/base.py", line 143, in _get_response
    response = response.render()
  File "/usr/local/lib/python3.8/site-packages/django/template/response.py", line 105, in render
    self.content = self.rendered_content
  File "/usr/local/lib/python3.8/site-packages/django/template/response.py", line 83, in rendered_content
    return template.render(context, self._request)
  File "/usr/local/lib/python3.8/site-packages/django/template/backends/django.py", line 61, in render
    return self.template.render(context)
  File "/usr/local/lib/python3.8/site-packages/django/template/base.py", line 171, in render
    return self._render(context)
  File "/usr/local/lib/python3.8/site-packages/django/template/base.py", line 163, in _render
    return self.nodelist.render(context)
  File "/usr/local/lib/python3.8/site-packages/django/template/base.py", line 936, in render
    bit = node.render_annotated(context)
  File "/usr/local/lib/python3.8/site-packages/django/template/base.py", line 903, in render_annotated
    return self.render(context)
  File "/usr/local/lib/python3.8/site-packages/django/template/loader_tags.py", line 150, in render
    return compiled_parent._render(context)
  File "/usr/local/lib/python3.8/site-packages/django/template/base.py", line 163, in _render
    return self.nodelist.render(context)
  File "/usr/local/lib/python3.8/site-packages/django/template/base.py", line 936, in render
    bit = node.render_annotated(context)
  File "/usr/local/lib/python3.8/site-packages/django/template/base.py", line 903, in render_annotated
    return self.render(context)
  File "/usr/local/lib/python3.8/site-packages/django/template/loader_tags.py", line 62, in render
    result = block.nodelist.render(context)
  File "/usr/local/lib/python3.8/site-packages/django/template/base.py", line 936, in render
    bit = node.render_annotated(context)
  File "/usr/local/lib/python3.8/site-packages/django/template/base.py", line 903, in render_annotated
    return self.render(context)
  File "/usr/local/lib/python3.8/site-packages/django/template/defaulttags.py", line 166, in render
    len_values = len(values)
  File "/usr/local/lib/python3.8/site-packages/django/db/models/query.py", line 258, in __len__
    self._fetch_all()
  File "/usr/local/lib/python3.8/site-packages/django/db/models/query.py", line 1261, in _fetch_all
    self._result_cache = list(self._iterable_class(self))
  File "/usr/local/lib/python3.8/site-packages/django/db/models/query.py", line 57, in __iter__
    results = compiler.execute_sql(chunked_fetch=self.chunked_fetch, chunk_size=self.chunk_size)
  File "/usr/local/lib/python3.8/site-packages/django/db/models/sql/compiler.py", line 1151, in execute_sql
    cursor.execute(sql, params)
  File "/usr/local/lib/python3.8/site-packages/django/db/backends/utils.py", line 100, in execute
    return super().execute(sql, params)
  File "/usr/local/lib/python3.8/site-packages/django/db/backends/utils.py", line 68, in execute
    return self._execute_with_wrappers(sql, params, many=False, executor=self._execute)
  File "/usr/local/lib/python3.8/site-packages/django/db/backends/utils.py", line 77, in _execute_with_wrappers
    return executor(sql, params, many, context)
  File "/usr/local/lib/python3.8/site-packages/django/db/backends/utils.py", line 86, in _execute
    return self.cursor.execute(sql, params)
  File "/usr/local/lib/python3.8/site-packages/django/db/utils.py", line 90, in __exit__
    raise dj_exc_value.with_traceback(traceback) from exc_value
  File "/usr/local/lib/python3.8/site-packages/django/db/backends/utils.py", line 86, in _execute
    return self.cursor.execute(sql, params)
django.db.utils.ProgrammingError: relation "jobs_job" does not exist
LINE 1: ...t", "jobs_job"."filled", "jobs_job"."salary" FROM "jobs_job"...
                                                             ^

Internal Server Error: /
Traceback (most recent call last):
  File "/usr/local/lib/python3.8/site-packages/django/db/backends/utils.py", line 86, in _execute
    return self.cursor.execute(sql, params)
psycopg2.errors.UndefinedTable: relation "jobs_job" does not exist
LINE 1: ...t", "jobs_job"."filled", "jobs_job"."salary" FROM "jobs_job"...
                                                             ^


The above exception was the direct cause of the following exception:

Traceback (most recent call last):
  File "/usr/local/lib/python3.8/site-packages/django/core/handlers/exception.py", line 34, in inner
    response = get_response(request)
  File "/usr/local/lib/python3.8/site-packages/django/core/handlers/base.py", line 145, in _get_response
    response = self.process_exception_by_middleware(e, request)
  File "/usr/local/lib/python3.8/site-packages/django/core/handlers/base.py", line 143, in _get_response
    response = response.render()
  File "/usr/local/lib/python3.8/site-packages/django/template/response.py", line 105, in render
    self.content = self.rendered_content
  File "/usr/local/lib/python3.8/site-packages/django/template/response.py", line 83, in rendered_content
    return template.render(context, self._request)
  File "/usr/local/lib/python3.8/site-packages/django/template/backends/django.py", line 61, in render
    return self.template.render(context)
  File "/usr/local/lib/python3.8/site-packages/django/template/base.py", line 171, in render
    return self._render(context)
  File "/usr/local/lib/python3.8/site-packages/django/template/base.py", line 163, in _render
    return self.nodelist.render(context)
  File "/usr/local/lib/python3.8/site-packages/django/template/base.py", line 936, in render
    bit = node.render_annotated(context)
  File "/usr/local/lib/python3.8/site-packages/django/template/base.py", line 903, in render_annotated
    return self.render(context)
  File "/usr/local/lib/python3.8/site-packages/django/template/loader_tags.py", line 150, in render
    return compiled_parent._render(context)
  File "/usr/local/lib/python3.8/site-packages/django/template/base.py", line 163, in _render
    return self.nodelist.render(context)
  File "/usr/local/lib/python3.8/site-packages/django/template/base.py", line 936, in render
    bit = node.render_annotated(context)
  File "/usr/local/lib/python3.8/site-packages/django/template/base.py", line 903, in render_annotated
    return self.render(context)
  File "/usr/local/lib/python3.8/site-packages/django/template/loader_tags.py", line 62, in render
    result = block.nodelist.render(context)
  File "/usr/local/lib/python3.8/site-packages/django/template/base.py", line 936, in render
    bit = node.render_annotated(context)
  File "/usr/local/lib/python3.8/site-packages/django/template/base.py", line 903, in render_annotated
    return self.render(context)
  File "/usr/local/lib/python3.8/site-packages/django/template/defaulttags.py", line 166, in render
    len_values = len(values)
  File "/usr/local/lib/python3.8/site-packages/django/db/models/query.py", line 258, in __len__
    self._fetch_all()
  File "/usr/local/lib/python3.8/site-packages/django/db/models/query.py", line 1261, in _fetch_all
    self._result_cache = list(self._iterable_class(self))
  File "/usr/local/lib/python3.8/site-packages/django/db/models/query.py", line 57, in __iter__
    results = compiler.execute_sql(chunked_fetch=self.chunked_fetch, chunk_size=self.chunk_size)
  File "/usr/local/lib/python3.8/site-packages/django/db/models/sql/compiler.py", line 1151, in execute_sql
    cursor.execute(sql, params)
  File "/usr/local/lib/python3.8/site-packages/django/db/backends/utils.py", line 100, in execute
    return super().execute(sql, params)
  File "/usr/local/lib/python3.8/site-packages/django/db/backends/utils.py", line 68, in execute
    return self._execute_with_wrappers(sql, params, many=False, executor=self._execute)
  File "/usr/local/lib/python3.8/site-packages/django/db/backends/utils.py", line 77, in _execute_with_wrappers
    return executor(sql, params, many, context)
  File "/usr/local/lib/python3.8/site-packages/django/db/backends/utils.py", line 86, in _execute
    return self.cursor.execute(sql, params)
  File "/usr/local/lib/python3.8/site-packages/django/db/utils.py", line 90, in __exit__
    raise dj_exc_value.with_traceback(traceback) from exc_value
  File "/usr/local/lib/python3.8/site-packages/django/db/backends/utils.py", line 86, in _execute
    return self.cursor.execute(sql, params)
django.db.utils.ProgrammingError: relation "jobs_job" does not exist
LINE 1: ...t", "jobs_job"."filled", "jobs_job"."salary" FROM "jobs_job"...
                                                             ^

"GET / HTTP/1.1" 500 207644
"GET / HTTP/1.1" 500 207644
Watching for file changes with StatReloader
Watching for file changes with StatReloader
Watching for file changes with StatReloader
Watching for file changes with StatReloader
Internal Server Error: /
Traceback (most recent call last):
  File "/usr/local/lib/python3.8/site-packages/django/db/backends/utils.py", line 86, in _execute
    return self.cursor.execute(sql, params)
psycopg2.errors.UndefinedTable: relation "jobs_job" does not exist
LINE 1: ...t", "jobs_job"."filled", "jobs_job"."salary" FROM "jobs_job"...
                                                             ^


The above exception was the direct cause of the following exception:

Traceback (most recent call last):
  File "/usr/local/lib/python3.8/site-packages/django/core/handlers/exception.py", line 34, in inner
    response = get_response(request)
  File "/usr/local/lib/python3.8/site-packages/django/core/handlers/base.py", line 145, in _get_response
    response = self.process_exception_by_middleware(e, request)
  File "/usr/local/lib/python3.8/site-packages/django/core/handlers/base.py", line 143, in _get_response
    response = response.render()
  File "/usr/local/lib/python3.8/site-packages/django/template/response.py", line 105, in render
    self.content = self.rendered_content
  File "/usr/local/lib/python3.8/site-packages/django/template/response.py", line 83, in rendered_content
    return template.render(context, self._request)
  File "/usr/local/lib/python3.8/site-packages/django/template/backends/django.py", line 61, in render
    return self.template.render(context)
  File "/usr/local/lib/python3.8/site-packages/django/template/base.py", line 171, in render
    return self._render(context)
  File "/usr/local/lib/python3.8/site-packages/django/template/base.py", line 163, in _render
    return self.nodelist.render(context)
  File "/usr/local/lib/python3.8/site-packages/django/template/base.py", line 936, in render
    bit = node.render_annotated(context)
  File "/usr/local/lib/python3.8/site-packages/django/template/base.py", line 903, in render_annotated
    return self.render(context)
  File "/usr/local/lib/python3.8/site-packages/django/template/loader_tags.py", line 150, in render
    return compiled_parent._render(context)
  File "/usr/local/lib/python3.8/site-packages/django/template/base.py", line 163, in _render
    return self.nodelist.render(context)
  File "/usr/local/lib/python3.8/site-packages/django/template/base.py", line 936, in render
    bit = node.render_annotated(context)
  File "/usr/local/lib/python3.8/site-packages/django/template/base.py", line 903, in render_annotated
    return self.render(context)
  File "/usr/local/lib/python3.8/site-packages/django/template/loader_tags.py", line 62, in render
    result = block.nodelist.render(context)
  File "/usr/local/lib/python3.8/site-packages/django/template/base.py", line 936, in render
    bit = node.render_annotated(context)
  File "/usr/local/lib/python3.8/site-packages/django/template/base.py", line 903, in render_annotated
    return self.render(context)
  File "/usr/local/lib/python3.8/site-packages/django/template/defaulttags.py", line 166, in render
    len_values = len(values)
  File "/usr/local/lib/python3.8/site-packages/django/db/models/query.py", line 258, in __len__
    self._fetch_all()
  File "/usr/local/lib/python3.8/site-packages/django/db/models/query.py", line 1261, in _fetch_all
    self._result_cache = list(self._iterable_class(self))
  File "/usr/local/lib/python3.8/site-packages/django/db/models/query.py", line 57, in __iter__
    results = compiler.execute_sql(chunked_fetch=self.chunked_fetch, chunk_size=self.chunk_size)
  File "/usr/local/lib/python3.8/site-packages/django/db/models/sql/compiler.py", line 1151, in execute_sql
    cursor.execute(sql, params)
  File "/usr/local/lib/python3.8/site-packages/django/db/backends/utils.py", line 100, in execute
    return super().execute(sql, params)
  File "/usr/local/lib/python3.8/site-packages/django/db/backends/utils.py", line 68, in execute
    return self._execute_with_wrappers(sql, params, many=False, executor=self._execute)
  File "/usr/local/lib/python3.8/site-packages/django/db/backends/utils.py", line 77, in _execute_with_wrappers
    return executor(sql, params, many, context)
  File "/usr/local/lib/python3.8/site-packages/django/db/backends/utils.py", line 86, in _execute
    return self.cursor.execute(sql, params)
  File "/usr/local/lib/python3.8/site-packages/django/db/utils.py", line 90, in __exit__
    raise dj_exc_value.with_traceback(traceback) from exc_value
  File "/usr/local/lib/python3.8/site-packages/django/db/backends/utils.py", line 86, in _execute
    return self.cursor.execute(sql, params)
django.db.utils.ProgrammingError: relation "jobs_job" does not exist
LINE 1: ...t", "jobs_job"."filled", "jobs_job"."salary" FROM "jobs_job"...
                                                             ^

Internal Server Error: /
Traceback (most recent call last):
  File "/usr/local/lib/python3.8/site-packages/django/db/backends/utils.py", line 86, in _execute
    return self.cursor.execute(sql, params)
psycopg2.errors.UndefinedTable: relation "jobs_job" does not exist
LINE 1: ...t", "jobs_job"."filled", "jobs_job"."salary" FROM "jobs_job"...
                                                             ^


The above exception was the direct cause of the following exception:

Traceback (most recent call last):
  File "/usr/local/lib/python3.8/site-packages/django/core/handlers/exception.py", line 34, in inner
    response = get_response(request)
  File "/usr/local/lib/python3.8/site-packages/django/core/handlers/base.py", line 145, in _get_response
    response = self.process_exception_by_middleware(e, request)
  File "/usr/local/lib/python3.8/site-packages/django/core/handlers/base.py", line 143, in _get_response
    response = response.render()
  File "/usr/local/lib/python3.8/site-packages/django/template/response.py", line 105, in render
    self.content = self.rendered_content
  File "/usr/local/lib/python3.8/site-packages/django/template/response.py", line 83, in rendered_content
    return template.render(context, self._request)
  File "/usr/local/lib/python3.8/site-packages/django/template/backends/django.py", line 61, in render
    return self.template.render(context)
  File "/usr/local/lib/python3.8/site-packages/django/template/base.py", line 171, in render
    return self._render(context)
  File "/usr/local/lib/python3.8/site-packages/django/template/base.py", line 163, in _render
    return self.nodelist.render(context)
  File "/usr/local/lib/python3.8/site-packages/django/template/base.py", line 936, in render
    bit = node.render_annotated(context)
  File "/usr/local/lib/python3.8/site-packages/django/template/base.py", line 903, in render_annotated
    return self.render(context)
  File "/usr/local/lib/python3.8/site-packages/django/template/loader_tags.py", line 150, in render
    return compiled_parent._render(context)
  File "/usr/local/lib/python3.8/site-packages/django/template/base.py", line 163, in _render
    return self.nodelist.render(context)
  File "/usr/local/lib/python3.8/site-packages/django/template/base.py", line 936, in render
    bit = node.render_annotated(context)
  File "/usr/local/lib/python3.8/site-packages/django/template/base.py", line 903, in render_annotated
    return self.render(context)
  File "/usr/local/lib/python3.8/site-packages/django/template/loader_tags.py", line 62, in render
    result = block.nodelist.render(context)
  File "/usr/local/lib/python3.8/site-packages/django/template/base.py", line 936, in render
    bit = node.render_annotated(context)
  File "/usr/local/lib/python3.8/site-packages/django/template/base.py", line 903, in render_annotated
    return self.render(context)
  File "/usr/local/lib/python3.8/site-packages/django/template/defaulttags.py", line 166, in render
    len_values = len(values)
  File "/usr/local/lib/python3.8/site-packages/django/db/models/query.py", line 258, in __len__
    self._fetch_all()
  File "/usr/local/lib/python3.8/site-packages/django/db/models/query.py", line 1261, in _fetch_all
    self._result_cache = list(self._iterable_class(self))
  File "/usr/local/lib/python3.8/site-packages/django/db/models/query.py", line 57, in __iter__
    results = compiler.execute_sql(chunked_fetch=self.chunked_fetch, chunk_size=self.chunk_size)
  File "/usr/local/lib/python3.8/site-packages/django/db/models/sql/compiler.py", line 1151, in execute_sql
    cursor.execute(sql, params)
  File "/usr/local/lib/python3.8/site-packages/django/db/backends/utils.py", line 100, in execute
    return super().execute(sql, params)
  File "/usr/local/lib/python3.8/site-packages/django/db/backends/utils.py", line 68, in execute
    return self._execute_with_wrappers(sql, params, many=False, executor=self._execute)
  File "/usr/local/lib/python3.8/site-packages/django/db/backends/utils.py", line 77, in _execute_with_wrappers
    return executor(sql, params, many, context)
  File "/usr/local/lib/python3.8/site-packages/django/db/backends/utils.py", line 86, in _execute
    return self.cursor.execute(sql, params)
  File "/usr/local/lib/python3.8/site-packages/django/db/utils.py", line 90, in __exit__
    raise dj_exc_value.with_traceback(traceback) from exc_value
  File "/usr/local/lib/python3.8/site-packages/django/db/backends/utils.py", line 86, in _execute
    return self.cursor.execute(sql, params)
django.db.utils.ProgrammingError: relation "jobs_job" does not exist
LINE 1: ...t", "jobs_job"."filled", "jobs_job"."salary" FROM "jobs_job"...
                                                             ^

"GET / HTTP/1.1" 500 206204
"GET / HTTP/1.1" 500 206204
Not Found: /favicon.ico
Not Found: /favicon.ico
"GET /favicon.ico HTTP/1.1" 404 4925
"GET /favicon.ico HTTP/1.1" 404 4925
"GET / HTTP/1.1" 200 8224
"GET / HTTP/1.1" 200 8224
"GET /static/vendor/bootstrap/css/bootstrap.min.css HTTP/1.1" 200 140930
"GET /static/vendor/bootstrap/css/bootstrap.min.css HTTP/1.1" 200 140930
"GET /static/vendor/owl.carousel/assets/owl.theme.default.css HTTP/1.1" 200 1380
"GET /static/vendor/owl.carousel/assets/owl.theme.default.css HTTP/1.1" 200 1380
"GET /static/vendor/font-awesome/css/font-awesome.min.css HTTP/1.1" 200 31396
"GET /static/vendor/font-awesome/css/font-awesome.min.css HTTP/1.1" 200 31396
"GET /static/vendor/owl.carousel/assets/owl.carousel.css HTTP/1.1" 200 4744
"GET /static/vendor/owl.carousel/assets/owl.carousel.css HTTP/1.1" 200 4744
"GET /static/vendor/jquery/jquery.min.js HTTP/1.1" 200 86927
"GET /static/vendor/jquery/jquery.min.js HTTP/1.1" 200 86927
"GET /static/css/style.default.css HTTP/1.1" 200 57334
"GET /static/css/style.default.css HTTP/1.1" 200 57334
"GET /static/css/custom.css HTTP/1.1" 200 25
"GET /static/css/custom.css HTTP/1.1" 200 25
"GET /static/vendor/jquery.cookie/jquery.cookie.js HTTP/1.1" 200 3121
"GET /static/vendor/bootstrap/js/bootstrap.min.js HTTP/1.1" 200 50731
"GET /static/vendor/bootstrap/js/bootstrap.min.js HTTP/1.1" 200 50731
"GET /static/vendor/jquery.cookie/jquery.cookie.js HTTP/1.1" 200 3121
"GET /static/vendor/popper.js/umd/popper.min.js HTTP/1.1" 200 20337
"GET /static/vendor/popper.js/umd/popper.min.js HTTP/1.1" 200 20337
"GET /static/vendor/owl.carousel/owl.carousel.min.js HTTP/1.1" 200 44342
"GET /static/vendor/owl.carousel/owl.carousel.min.js HTTP/1.1" 200 44342
"GET /static/img/logo-small.png HTTP/1.1" 200 5152
"GET /static/img/logo-small.png HTTP/1.1" 200 5152
"GET /static/vendor/bootstrap-select/js/bootstrap-select.min.js HTTP/1.1" 200 44448
"GET /static/vendor/bootstrap-select/js/bootstrap-select.min.js HTTP/1.1" 200 44448
"GET /static/js/front.js HTTP/1.1" 200 8053
"GET /static/js/front.js HTTP/1.1" 200 8053
"GET /static/img/meeting.jpg HTTP/1.1" 200 144248
"GET /static/img/meeting.jpg HTTP/1.1" 200 144248
"GET /static/img/startup.jpg HTTP/1.1" 404 1669
"GET /static/img/startup.jpg HTTP/1.1" 404 1669
Not Found: /favicon.png
Not Found: /favicon.png
"GET /favicon.png HTTP/1.1" 404 4925
"GET /favicon.png HTTP/1.1" 404 4925
"GET /login HTTP/1.1" 200 6545
"GET /login HTTP/1.1" 200 6545
Watching for file changes with StatReloader
Watching for file changes with StatReloader
Internal Server Error: /
Traceback (most recent call last):
  File "/usr/local/lib/python3.8/site-packages/django/db/backends/utils.py", line 86, in _execute
    return self.cursor.execute(sql, params)
psycopg2.errors.UndefinedTable: relation "jobs_job" does not exist
LINE 1: ...t", "jobs_job"."filled", "jobs_job"."salary" FROM "jobs_job"...
                                                             ^


The above exception was the direct cause of the following exception:

Traceback (most recent call last):
  File "/usr/local/lib/python3.8/site-packages/django/core/handlers/exception.py", line 34, in inner
    response = get_response(request)
  File "/usr/local/lib/python3.8/site-packages/django/core/handlers/base.py", line 145, in _get_response
    response = self.process_exception_by_middleware(e, request)
  File "/usr/local/lib/python3.8/site-packages/django/core/handlers/base.py", line 143, in _get_response
    response = response.render()
  File "/usr/local/lib/python3.8/site-packages/django/template/response.py", line 105, in render
    self.content = self.rendered_content
  File "/usr/local/lib/python3.8/site-packages/django/template/response.py", line 83, in rendered_content
    return template.render(context, self._request)
  File "/usr/local/lib/python3.8/site-packages/django/template/backends/django.py", line 61, in render
    return self.template.render(context)
  File "/usr/local/lib/python3.8/site-packages/django/template/base.py", line 171, in render
    return self._render(context)
  File "/usr/local/lib/python3.8/site-packages/django/template/base.py", line 163, in _render
    return self.nodelist.render(context)
  File "/usr/local/lib/python3.8/site-packages/django/template/base.py", line 936, in render
    bit = node.render_annotated(context)
  File "/usr/local/lib/python3.8/site-packages/django/template/base.py", line 903, in render_annotated
    return self.render(context)
  File "/usr/local/lib/python3.8/site-packages/django/template/loader_tags.py", line 150, in render
    return compiled_parent._render(context)
  File "/usr/local/lib/python3.8/site-packages/django/template/base.py", line 163, in _render
    return self.nodelist.render(context)
  File "/usr/local/lib/python3.8/site-packages/django/template/base.py", line 936, in render
    bit = node.render_annotated(context)
  File "/usr/local/lib/python3.8/site-packages/django/template/base.py", line 903, in render_annotated
    return self.render(context)
  File "/usr/local/lib/python3.8/site-packages/django/template/loader_tags.py", line 62, in render
    result = block.nodelist.render(context)
  File "/usr/local/lib/python3.8/site-packages/django/template/base.py", line 936, in render
    bit = node.render_annotated(context)
  File "/usr/local/lib/python3.8/site-packages/django/template/base.py", line 903, in render_annotated
    return self.render(context)
  File "/usr/local/lib/python3.8/site-packages/django/template/defaulttags.py", line 166, in render
    len_values = len(values)
  File "/usr/local/lib/python3.8/site-packages/django/db/models/query.py", line 258, in __len__
    self._fetch_all()
  File "/usr/local/lib/python3.8/site-packages/django/db/models/query.py", line 1261, in _fetch_all
    self._result_cache = list(self._iterable_class(self))
  File "/usr/local/lib/python3.8/site-packages/django/db/models/query.py", line 57, in __iter__
    results = compiler.execute_sql(chunked_fetch=self.chunked_fetch, chunk_size=self.chunk_size)
  File "/usr/local/lib/python3.8/site-packages/django/db/models/sql/compiler.py", line 1151, in execute_sql
    cursor.execute(sql, params)
  File "/usr/local/lib/python3.8/site-packages/django/db/backends/utils.py", line 100, in execute
    return super().execute(sql, params)
  File "/usr/local/lib/python3.8/site-packages/django/db/backends/utils.py", line 68, in execute
    return self._execute_with_wrappers(sql, params, many=False, executor=self._execute)
  File "/usr/local/lib/python3.8/site-packages/django/db/backends/utils.py", line 77, in _execute_with_wrappers
    return executor(sql, params, many, context)
  File "/usr/local/lib/python3.8/site-packages/django/db/backends/utils.py", line 86, in _execute
    return self.cursor.execute(sql, params)
  File "/usr/local/lib/python3.8/site-packages/django/db/utils.py", line 90, in __exit__
    raise dj_exc_value.with_traceback(traceback) from exc_value
  File "/usr/local/lib/python3.8/site-packages/django/db/backends/utils.py", line 86, in _execute
    return self.cursor.execute(sql, params)
django.db.utils.ProgrammingError: relation "jobs_job" does not exist
LINE 1: ...t", "jobs_job"."filled", "jobs_job"."salary" FROM "jobs_job"...
                                                             ^

Internal Server Error: /
Traceback (most recent call last):
  File "/usr/local/lib/python3.8/site-packages/django/db/backends/utils.py", line 86, in _execute
    return self.cursor.execute(sql, params)
psycopg2.errors.UndefinedTable: relation "jobs_job" does not exist
LINE 1: ...t", "jobs_job"."filled", "jobs_job"."salary" FROM "jobs_job"...
                                                             ^


The above exception was the direct cause of the following exception:

Traceback (most recent call last):
  File "/usr/local/lib/python3.8/site-packages/django/core/handlers/exception.py", line 34, in inner
    response = get_response(request)
  File "/usr/local/lib/python3.8/site-packages/django/core/handlers/base.py", line 145, in _get_response
    response = self.process_exception_by_middleware(e, request)
  File "/usr/local/lib/python3.8/site-packages/django/core/handlers/base.py", line 143, in _get_response
    response = response.render()
  File "/usr/local/lib/python3.8/site-packages/django/template/response.py", line 105, in render
    self.content = self.rendered_content
  File "/usr/local/lib/python3.8/site-packages/django/template/response.py", line 83, in rendered_content
    return template.render(context, self._request)
  File "/usr/local/lib/python3.8/site-packages/django/template/backends/django.py", line 61, in render
    return self.template.render(context)
  File "/usr/local/lib/python3.8/site-packages/django/template/base.py", line 171, in render
    return self._render(context)
  File "/usr/local/lib/python3.8/site-packages/django/template/base.py", line 163, in _render
    return self.nodelist.render(context)
  File "/usr/local/lib/python3.8/site-packages/django/template/base.py", line 936, in render
    bit = node.render_annotated(context)
  File "/usr/local/lib/python3.8/site-packages/django/template/base.py", line 903, in render_annotated
    return self.render(context)
  File "/usr/local/lib/python3.8/site-packages/django/template/loader_tags.py", line 150, in render
    return compiled_parent._render(context)
  File "/usr/local/lib/python3.8/site-packages/django/template/base.py", line 163, in _render
    return self.nodelist.render(context)
  File "/usr/local/lib/python3.8/site-packages/django/template/base.py", line 936, in render
    bit = node.render_annotated(context)
  File "/usr/local/lib/python3.8/site-packages/django/template/base.py", line 903, in render_annotated
    return self.render(context)
  File "/usr/local/lib/python3.8/site-packages/django/template/loader_tags.py", line 62, in render
    result = block.nodelist.render(context)
  File "/usr/local/lib/python3.8/site-packages/django/template/base.py", line 936, in render
    bit = node.render_annotated(context)
  File "/usr/local/lib/python3.8/site-packages/django/template/base.py", line 903, in render_annotated
    return self.render(context)
  File "/usr/local/lib/python3.8/site-packages/django/template/defaulttags.py", line 166, in render
    len_values = len(values)
  File "/usr/local/lib/python3.8/site-packages/django/db/models/query.py", line 258, in __len__
    self._fetch_all()
  File "/usr/local/lib/python3.8/site-packages/django/db/models/query.py", line 1261, in _fetch_all
    self._result_cache = list(self._iterable_class(self))
  File "/usr/local/lib/python3.8/site-packages/django/db/models/query.py", line 57, in __iter__
    results = compiler.execute_sql(chunked_fetch=self.chunked_fetch, chunk_size=self.chunk_size)
  File "/usr/local/lib/python3.8/site-packages/django/db/models/sql/compiler.py", line 1151, in execute_sql
    cursor.execute(sql, params)
  File "/usr/local/lib/python3.8/site-packages/django/db/backends/utils.py", line 100, in execute
    return super().execute(sql, params)
  File "/usr/local/lib/python3.8/site-packages/django/db/backends/utils.py", line 68, in execute
    return self._execute_with_wrappers(sql, params, many=False, executor=self._execute)
  File "/usr/local/lib/python3.8/site-packages/django/db/backends/utils.py", line 77, in _execute_with_wrappers
    return executor(sql, params, many, context)
  File "/usr/local/lib/python3.8/site-packages/django/db/backends/utils.py", line 86, in _execute
    return self.cursor.execute(sql, params)
  File "/usr/local/lib/python3.8/site-packages/django/db/utils.py", line 90, in __exit__
    raise dj_exc_value.with_traceback(traceback) from exc_value
  File "/usr/local/lib/python3.8/site-packages/django/db/backends/utils.py", line 86, in _execute
    return self.cursor.execute(sql, params)
django.db.utils.ProgrammingError: relation "jobs_job" does not exist
LINE 1: ...t", "jobs_job"."filled", "jobs_job"."salary" FROM "jobs_job"...
                                                             ^

"GET / HTTP/1.1" 500 207187
"GET / HTTP/1.1" 500 207187
Not Found: /favicon.ico
Not Found: /favicon.ico
"GET /favicon.ico HTTP/1.1" 404 4925
"GET /favicon.ico HTTP/1.1" 404 4925
Watching for file changes with StatReloader
Watching for file changes with StatReloader
Internal Server Error: /
Traceback (most recent call last):
  File "/usr/local/lib/python3.8/site-packages/django/db/backends/utils.py", line 86, in _execute
    return self.cursor.execute(sql, params)
psycopg2.errors.UndefinedTable: relation "jobs_job" does not exist
LINE 1: ...t", "jobs_job"."filled", "jobs_job"."salary" FROM "jobs_job"...
                                                             ^


The above exception was the direct cause of the following exception:

Traceback (most recent call last):
  File "/usr/local/lib/python3.8/site-packages/django/core/handlers/exception.py", line 34, in inner
    response = get_response(request)
  File "/usr/local/lib/python3.8/site-packages/django/core/handlers/base.py", line 145, in _get_response
    response = self.process_exception_by_middleware(e, request)
  File "/usr/local/lib/python3.8/site-packages/django/core/handlers/base.py", line 143, in _get_response
    response = response.render()
  File "/usr/local/lib/python3.8/site-packages/django/template/response.py", line 105, in render
    self.content = self.rendered_content
  File "/usr/local/lib/python3.8/site-packages/django/template/response.py", line 83, in rendered_content
    return template.render(context, self._request)
  File "/usr/local/lib/python3.8/site-packages/django/template/backends/django.py", line 61, in render
    return self.template.render(context)
  File "/usr/local/lib/python3.8/site-packages/django/template/base.py", line 171, in render
    return self._render(context)
  File "/usr/local/lib/python3.8/site-packages/django/template/base.py", line 163, in _render
    return self.nodelist.render(context)
  File "/usr/local/lib/python3.8/site-packages/django/template/base.py", line 936, in render
    bit = node.render_annotated(context)
  File "/usr/local/lib/python3.8/site-packages/django/template/base.py", line 903, in render_annotated
    return self.render(context)
  File "/usr/local/lib/python3.8/site-packages/django/template/loader_tags.py", line 150, in render
    return compiled_parent._render(context)
  File "/usr/local/lib/python3.8/site-packages/django/template/base.py", line 163, in _render
    return self.nodelist.render(context)
  File "/usr/local/lib/python3.8/site-packages/django/template/base.py", line 936, in render
    bit = node.render_annotated(context)
  File "/usr/local/lib/python3.8/site-packages/django/template/base.py", line 903, in render_annotated
    return self.render(context)
  File "/usr/local/lib/python3.8/site-packages/django/template/loader_tags.py", line 62, in render
    result = block.nodelist.render(context)
  File "/usr/local/lib/python3.8/site-packages/django/template/base.py", line 936, in render
    bit = node.render_annotated(context)
  File "/usr/local/lib/python3.8/site-packages/django/template/base.py", line 903, in render_annotated
    return self.render(context)
  File "/usr/local/lib/python3.8/site-packages/django/template/defaulttags.py", line 166, in render
    len_values = len(values)
  File "/usr/local/lib/python3.8/site-packages/django/db/models/query.py", line 258, in __len__
    self._fetch_all()
  File "/usr/local/lib/python3.8/site-packages/django/db/models/query.py", line 1261, in _fetch_all
    self._result_cache = list(self._iterable_class(self))
  File "/usr/local/lib/python3.8/site-packages/django/db/models/query.py", line 57, in __iter__
    results = compiler.execute_sql(chunked_fetch=self.chunked_fetch, chunk_size=self.chunk_size)
  File "/usr/local/lib/python3.8/site-packages/django/db/models/sql/compiler.py", line 1151, in execute_sql
    cursor.execute(sql, params)
  File "/usr/local/lib/python3.8/site-packages/django/db/backends/utils.py", line 100, in execute
    return super().execute(sql, params)
  File "/usr/local/lib/python3.8/site-packages/django/db/backends/utils.py", line 68, in execute
    return self._execute_with_wrappers(sql, params, many=False, executor=self._execute)
  File "/usr/local/lib/python3.8/site-packages/django/db/backends/utils.py", line 77, in _execute_with_wrappers
    return executor(sql, params, many, context)
  File "/usr/local/lib/python3.8/site-packages/django/db/backends/utils.py", line 86, in _execute
    return self.cursor.execute(sql, params)
  File "/usr/local/lib/python3.8/site-packages/django/db/utils.py", line 90, in __exit__
    raise dj_exc_value.with_traceback(traceback) from exc_value
  File "/usr/local/lib/python3.8/site-packages/django/db/backends/utils.py", line 86, in _execute
    return self.cursor.execute(sql, params)
django.db.utils.ProgrammingError: relation "jobs_job" does not exist
LINE 1: ...t", "jobs_job"."filled", "jobs_job"."salary" FROM "jobs_job"...
                                                             ^

Internal Server Error: /
Traceback (most recent call last):
  File "/usr/local/lib/python3.8/site-packages/django/db/backends/utils.py", line 86, in _execute
    return self.cursor.execute(sql, params)
psycopg2.errors.UndefinedTable: relation "jobs_job" does not exist
LINE 1: ...t", "jobs_job"."filled", "jobs_job"."salary" FROM "jobs_job"...
                                                             ^


The above exception was the direct cause of the following exception:

Traceback (most recent call last):
  File "/usr/local/lib/python3.8/site-packages/django/core/handlers/exception.py", line 34, in inner
    response = get_response(request)
  File "/usr/local/lib/python3.8/site-packages/django/core/handlers/base.py", line 145, in _get_response
    response = self.process_exception_by_middleware(e, request)
  File "/usr/local/lib/python3.8/site-packages/django/core/handlers/base.py", line 143, in _get_response
    response = response.render()
  File "/usr/local/lib/python3.8/site-packages/django/template/response.py", line 105, in render
    self.content = self.rendered_content
  File "/usr/local/lib/python3.8/site-packages/django/template/response.py", line 83, in rendered_content
    return template.render(context, self._request)
  File "/usr/local/lib/python3.8/site-packages/django/template/backends/django.py", line 61, in render
    return self.template.render(context)
  File "/usr/local/lib/python3.8/site-packages/django/template/base.py", line 171, in render
    return self._render(context)
  File "/usr/local/lib/python3.8/site-packages/django/template/base.py", line 163, in _render
    return self.nodelist.render(context)
  File "/usr/local/lib/python3.8/site-packages/django/template/base.py", line 936, in render
    bit = node.render_annotated(context)
  File "/usr/local/lib/python3.8/site-packages/django/template/base.py", line 903, in render_annotated
    return self.render(context)
  File "/usr/local/lib/python3.8/site-packages/django/template/loader_tags.py", line 150, in render
    return compiled_parent._render(context)
  File "/usr/local/lib/python3.8/site-packages/django/template/base.py", line 163, in _render
    return self.nodelist.render(context)
  File "/usr/local/lib/python3.8/site-packages/django/template/base.py", line 936, in render
    bit = node.render_annotated(context)
  File "/usr/local/lib/python3.8/site-packages/django/template/base.py", line 903, in render_annotated
    return self.render(context)
  File "/usr/local/lib/python3.8/site-packages/django/template/loader_tags.py", line 62, in render
    result = block.nodelist.render(context)
  File "/usr/local/lib/python3.8/site-packages/django/template/base.py", line 936, in render
    bit = node.render_annotated(context)
  File "/usr/local/lib/python3.8/site-packages/django/template/base.py", line 903, in render_annotated
    return self.render(context)
  File "/usr/local/lib/python3.8/site-packages/django/template/defaulttags.py", line 166, in render
    len_values = len(values)
  File "/usr/local/lib/python3.8/site-packages/django/db/models/query.py", line 258, in __len__
    self._fetch_all()
  File "/usr/local/lib/python3.8/site-packages/django/db/models/query.py", line 1261, in _fetch_all
    self._result_cache = list(self._iterable_class(self))
  File "/usr/local/lib/python3.8/site-packages/django/db/models/query.py", line 57, in __iter__
    results = compiler.execute_sql(chunked_fetch=self.chunked_fetch, chunk_size=self.chunk_size)
  File "/usr/local/lib/python3.8/site-packages/django/db/models/sql/compiler.py", line 1151, in execute_sql
    cursor.execute(sql, params)
  File "/usr/local/lib/python3.8/site-packages/django/db/backends/utils.py", line 100, in execute
    return super().execute(sql, params)
  File "/usr/local/lib/python3.8/site-packages/django/db/backends/utils.py", line 68, in execute
    return self._execute_with_wrappers(sql, params, many=False, executor=self._execute)
  File "/usr/local/lib/python3.8/site-packages/django/db/backends/utils.py", line 77, in _execute_with_wrappers
    return executor(sql, params, many, context)
  File "/usr/local/lib/python3.8/site-packages/django/db/backends/utils.py", line 86, in _execute
    return self.cursor.execute(sql, params)
  File "/usr/local/lib/python3.8/site-packages/django/db/utils.py", line 90, in __exit__
    raise dj_exc_value.with_traceback(traceback) from exc_value
  File "/usr/local/lib/python3.8/site-packages/django/db/backends/utils.py", line 86, in _execute
    return self.cursor.execute(sql, params)
django.db.utils.ProgrammingError: relation "jobs_job" does not exist
LINE 1: ...t", "jobs_job"."filled", "jobs_job"."salary" FROM "jobs_job"...
                                                             ^

"GET / HTTP/1.1" 500 207189
"GET / HTTP/1.1" 500 207189
Not Found: /favicon.ico
Not Found: /favicon.ico
"GET /favicon.ico HTTP/1.1" 404 4925
"GET /favicon.ico HTTP/1.1" 404 4925
"GET /admin HTTP/1.1" 301 0
"GET /admin HTTP/1.1" 301 0
Internal Server Error: /admin/
Traceback (most recent call last):
  File "/usr/local/lib/python3.8/site-packages/django/contrib/sessions/backends/base.py", line 199, in _get_session
    return self._session_cache
AttributeError: 'SessionStore' object has no attribute '_session_cache'

During handling of the above exception, another exception occurred:

Traceback (most recent call last):
  File "/usr/local/lib/python3.8/site-packages/django/db/backends/utils.py", line 86, in _execute
    return self.cursor.execute(sql, params)
psycopg2.errors.UndefinedTable: relation "django_session" does not exist
LINE 1: ...ession_data", "django_session"."expire_date" FROM "django_se...
                                                             ^


The above exception was the direct cause of the following exception:

Traceback (most recent call last):
  File "/usr/local/lib/python3.8/site-packages/django/core/handlers/exception.py", line 34, in inner
    response = get_response(request)
  File "/usr/local/lib/python3.8/site-packages/django/core/handlers/base.py", line 115, in _get_response
    response = self.process_exception_by_middleware(e, request)
  File "/usr/local/lib/python3.8/site-packages/django/core/handlers/base.py", line 113, in _get_response
    response = wrapped_callback(request, *callback_args, **callback_kwargs)
  File "/usr/local/lib/python3.8/site-packages/django/contrib/admin/sites.py", line 249, in wrapper
    return self.admin_view(view, cacheable)(*args, **kwargs)
  File "/usr/local/lib/python3.8/site-packages/django/utils/decorators.py", line 130, in _wrapped_view
    response = view_func(request, *args, **kwargs)
  File "/usr/local/lib/python3.8/site-packages/django/views/decorators/cache.py", line 44, in _wrapped_view_func
    response = view_func(request, *args, **kwargs)
  File "/usr/local/lib/python3.8/site-packages/django/contrib/admin/sites.py", line 220, in inner
    if not self.has_permission(request):
  File "/usr/local/lib/python3.8/site-packages/django/contrib/admin/sites.py", line 194, in has_permission
    return request.user.is_active and request.user.is_staff
  File "/usr/local/lib/python3.8/site-packages/django/utils/functional.py", line 224, in inner
    self._setup()
  File "/usr/local/lib/python3.8/site-packages/django/utils/functional.py", line 360, in _setup
    self._wrapped = self._setupfunc()
  File "/usr/local/lib/python3.8/site-packages/django/contrib/auth/middleware.py", line 24, in <lambda>
    request.user = SimpleLazyObject(lambda: get_user(request))
  File "/usr/local/lib/python3.8/site-packages/django/contrib/auth/middleware.py", line 12, in get_user
    request._cached_user = auth.get_user(request)
  File "/usr/local/lib/python3.8/site-packages/django/contrib/auth/__init__.py", line 173, in get_user
    user_id = _get_user_session_key(request)
  File "/usr/local/lib/python3.8/site-packages/django/contrib/auth/__init__.py", line 58, in _get_user_session_key
    return get_user_model()._meta.pk.to_python(request.session[SESSION_KEY])
  File "/usr/local/lib/python3.8/site-packages/django/contrib/sessions/backends/base.py", line 64, in __getitem__
    return self._session[key]
  File "/usr/local/lib/python3.8/site-packages/django/contrib/sessions/backends/base.py", line 204, in _get_session
    self._session_cache = self.load()
  File "/usr/local/lib/python3.8/site-packages/django/contrib/sessions/backends/db.py", line 43, in load
    s = self._get_session_from_db()
  File "/usr/local/lib/python3.8/site-packages/django/contrib/sessions/backends/db.py", line 32, in _get_session_from_db
    return self.model.objects.get(
  File "/usr/local/lib/python3.8/site-packages/django/db/models/manager.py", line 82, in manager_method
    return getattr(self.get_queryset(), name)(*args, **kwargs)
  File "/usr/local/lib/python3.8/site-packages/django/db/models/query.py", line 411, in get
    num = len(clone)
  File "/usr/local/lib/python3.8/site-packages/django/db/models/query.py", line 258, in __len__
    self._fetch_all()
  File "/usr/local/lib/python3.8/site-packages/django/db/models/query.py", line 1261, in _fetch_all
    self._result_cache = list(self._iterable_class(self))
  File "/usr/local/lib/python3.8/site-packages/django/db/models/query.py", line 57, in __iter__
    results = compiler.execute_sql(chunked_fetch=self.chunked_fetch, chunk_size=self.chunk_size)
  File "/usr/local/lib/python3.8/site-packages/django/db/models/sql/compiler.py", line 1151, in execute_sql
    cursor.execute(sql, params)
  File "/usr/local/lib/python3.8/site-packages/django/db/backends/utils.py", line 100, in execute
    return super().execute(sql, params)
  File "/usr/local/lib/python3.8/site-packages/django/db/backends/utils.py", line 68, in execute
    return self._execute_with_wrappers(sql, params, many=False, executor=self._execute)
  File "/usr/local/lib/python3.8/site-packages/django/db/backends/utils.py", line 77, in _execute_with_wrappers
    return executor(sql, params, many, context)
  File "/usr/local/lib/python3.8/site-packages/django/db/backends/utils.py", line 86, in _execute
    return self.cursor.execute(sql, params)
  File "/usr/local/lib/python3.8/site-packages/django/db/utils.py", line 90, in __exit__
    raise dj_exc_value.with_traceback(traceback) from exc_value
  File "/usr/local/lib/python3.8/site-packages/django/db/backends/utils.py", line 86, in _execute
    return self.cursor.execute(sql, params)
django.db.utils.ProgrammingError: relation "django_session" does not exist
LINE 1: ...ession_data", "django_session"."expire_date" FROM "django_se...
                                                             ^

Internal Server Error: /admin/
Traceback (most recent call last):
  File "/usr/local/lib/python3.8/site-packages/django/contrib/sessions/backends/base.py", line 199, in _get_session
    return self._session_cache
AttributeError: 'SessionStore' object has no attribute '_session_cache'

During handling of the above exception, another exception occurred:

Traceback (most recent call last):
  File "/usr/local/lib/python3.8/site-packages/django/db/backends/utils.py", line 86, in _execute
    return self.cursor.execute(sql, params)
psycopg2.errors.UndefinedTable: relation "django_session" does not exist
LINE 1: ...ession_data", "django_session"."expire_date" FROM "django_se...
                                                             ^


The above exception was the direct cause of the following exception:

Traceback (most recent call last):
  File "/usr/local/lib/python3.8/site-packages/django/core/handlers/exception.py", line 34, in inner
    response = get_response(request)
  File "/usr/local/lib/python3.8/site-packages/django/core/handlers/base.py", line 115, in _get_response
    response = self.process_exception_by_middleware(e, request)
  File "/usr/local/lib/python3.8/site-packages/django/core/handlers/base.py", line 113, in _get_response
    response = wrapped_callback(request, *callback_args, **callback_kwargs)
  File "/usr/local/lib/python3.8/site-packages/django/contrib/admin/sites.py", line 249, in wrapper
    return self.admin_view(view, cacheable)(*args, **kwargs)
  File "/usr/local/lib/python3.8/site-packages/django/utils/decorators.py", line 130, in _wrapped_view
    response = view_func(request, *args, **kwargs)
  File "/usr/local/lib/python3.8/site-packages/django/views/decorators/cache.py", line 44, in _wrapped_view_func
    response = view_func(request, *args, **kwargs)
  File "/usr/local/lib/python3.8/site-packages/django/contrib/admin/sites.py", line 220, in inner
    if not self.has_permission(request):
  File "/usr/local/lib/python3.8/site-packages/django/contrib/admin/sites.py", line 194, in has_permission
    return request.user.is_active and request.user.is_staff
  File "/usr/local/lib/python3.8/site-packages/django/utils/functional.py", line 224, in inner
    self._setup()
  File "/usr/local/lib/python3.8/site-packages/django/utils/functional.py", line 360, in _setup
    self._wrapped = self._setupfunc()
  File "/usr/local/lib/python3.8/site-packages/django/contrib/auth/middleware.py", line 24, in <lambda>
    request.user = SimpleLazyObject(lambda: get_user(request))
  File "/usr/local/lib/python3.8/site-packages/django/contrib/auth/middleware.py", line 12, in get_user
    request._cached_user = auth.get_user(request)
  File "/usr/local/lib/python3.8/site-packages/django/contrib/auth/__init__.py", line 173, in get_user
    user_id = _get_user_session_key(request)
  File "/usr/local/lib/python3.8/site-packages/django/contrib/auth/__init__.py", line 58, in _get_user_session_key
    return get_user_model()._meta.pk.to_python(request.session[SESSION_KEY])
  File "/usr/local/lib/python3.8/site-packages/django/contrib/sessions/backends/base.py", line 64, in __getitem__
    return self._session[key]
  File "/usr/local/lib/python3.8/site-packages/django/contrib/sessions/backends/base.py", line 204, in _get_session
    self._session_cache = self.load()
  File "/usr/local/lib/python3.8/site-packages/django/contrib/sessions/backends/db.py", line 43, in load
    s = self._get_session_from_db()
  File "/usr/local/lib/python3.8/site-packages/django/contrib/sessions/backends/db.py", line 32, in _get_session_from_db
    return self.model.objects.get(
  File "/usr/local/lib/python3.8/site-packages/django/db/models/manager.py", line 82, in manager_method
    return getattr(self.get_queryset(), name)(*args, **kwargs)
  File "/usr/local/lib/python3.8/site-packages/django/db/models/query.py", line 411, in get
    num = len(clone)
  File "/usr/local/lib/python3.8/site-packages/django/db/models/query.py", line 258, in __len__
    self._fetch_all()
  File "/usr/local/lib/python3.8/site-packages/django/db/models/query.py", line 1261, in _fetch_all
    self._result_cache = list(self._iterable_class(self))
  File "/usr/local/lib/python3.8/site-packages/django/db/models/query.py", line 57, in __iter__
    results = compiler.execute_sql(chunked_fetch=self.chunked_fetch, chunk_size=self.chunk_size)
  File "/usr/local/lib/python3.8/site-packages/django/db/models/sql/compiler.py", line 1151, in execute_sql
    cursor.execute(sql, params)
  File "/usr/local/lib/python3.8/site-packages/django/db/backends/utils.py", line 100, in execute
    return super().execute(sql, params)
  File "/usr/local/lib/python3.8/site-packages/django/db/backends/utils.py", line 68, in execute
    return self._execute_with_wrappers(sql, params, many=False, executor=self._execute)
  File "/usr/local/lib/python3.8/site-packages/django/db/backends/utils.py", line 77, in _execute_with_wrappers
    return executor(sql, params, many, context)
  File "/usr/local/lib/python3.8/site-packages/django/db/backends/utils.py", line 86, in _execute
    return self.cursor.execute(sql, params)
  File "/usr/local/lib/python3.8/site-packages/django/db/utils.py", line 90, in __exit__
    raise dj_exc_value.with_traceback(traceback) from exc_value
  File "/usr/local/lib/python3.8/site-packages/django/db/backends/utils.py", line 86, in _execute
    return self.cursor.execute(sql, params)
django.db.utils.ProgrammingError: relation "django_session" does not exist
LINE 1: ...ession_data", "django_session"."expire_date" FROM "django_se...
                                                             ^

"GET /admin/ HTTP/1.1" 500 190282
"GET /admin/ HTTP/1.1" 500 190282
Watching for file changes with StatReloader
Watching for file changes with StatReloader
Watching for file changes with StatReloader
Watching for file changes with StatReloader
"GET / HTTP/1.1" 200 8224
"GET / HTTP/1.1" 200 8224
"GET /static/vendor/bootstrap/css/bootstrap.min.css HTTP/1.1" 304 0
"GET /static/vendor/font-awesome/css/font-awesome.min.css HTTP/1.1" 304 0
"GET /static/vendor/font-awesome/css/font-awesome.min.css HTTP/1.1" 304 0
"GET /static/vendor/bootstrap/css/bootstrap.min.css HTTP/1.1" 304 0
"GET /static/vendor/owl.carousel/assets/owl.theme.default.css HTTP/1.1" 304 0
"GET /static/vendor/owl.carousel/assets/owl.carousel.css HTTP/1.1" 304 0
"GET /static/vendor/owl.carousel/assets/owl.carousel.css HTTP/1.1" 304 0
"GET /static/vendor/owl.carousel/assets/owl.theme.default.css HTTP/1.1" 304 0
"GET /static/css/style.default.css HTTP/1.1" 304 0
"GET /static/css/style.default.css HTTP/1.1" 304 0
"GET /static/css/custom.css HTTP/1.1" 304 0
"GET /static/css/custom.css HTTP/1.1" 304 0
"GET /static/vendor/jquery/jquery.min.js HTTP/1.1" 304 0
"GET /static/vendor/jquery/jquery.min.js HTTP/1.1" 304 0
"GET /static/img/logo-small.png HTTP/1.1" 304 0
"GET /static/img/logo-small.png HTTP/1.1" 304 0
"GET /static/vendor/popper.js/umd/popper.min.js HTTP/1.1" 304 0
"GET /static/vendor/popper.js/umd/popper.min.js HTTP/1.1" 304 0
"GET /static/vendor/bootstrap/js/bootstrap.min.js HTTP/1.1" 304 0
"GET /static/vendor/bootstrap/js/bootstrap.min.js HTTP/1.1" 304 0
"GET /static/vendor/jquery.cookie/jquery.cookie.js HTTP/1.1" 304 0
"GET /static/vendor/jquery.cookie/jquery.cookie.js HTTP/1.1" 304 0
"GET /static/vendor/bootstrap-select/js/bootstrap-select.min.js HTTP/1.1" 304 0
"GET /static/vendor/bootstrap-select/js/bootstrap-select.min.js HTTP/1.1" 304 0
"GET /static/vendor/owl.carousel/owl.carousel.min.js HTTP/1.1" 304 0
"GET /static/vendor/owl.carousel/owl.carousel.min.js HTTP/1.1" 304 0
"GET /static/js/front.js HTTP/1.1" 304 0
"GET /static/js/front.js HTTP/1.1" 304 0
"GET /static/img/startup.jpg HTTP/1.1" 404 1669
"GET /static/img/startup.jpg HTTP/1.1" 404 1669
"GET /static/img/meeting.jpg HTTP/1.1" 304 0
"GET /static/img/meeting.jpg HTTP/1.1" 304 0
Not Found: /favicon.png
Not Found: /favicon.png
"GET /favicon.png HTTP/1.1" 404 4925
"GET /favicon.png HTTP/1.1" 404 4925
Watching for file changes with StatReloader
Watching for file changes with StatReloader
"GET / HTTP/1.1" 200 8224
"GET / HTTP/1.1" 200 8224
"GET /static/img/startup.jpg HTTP/1.1" 404 1669
"GET /static/img/startup.jpg HTTP/1.1" 404 1669
Not Found: /favicon.png
Not Found: /favicon.png
"GET /favicon.png HTTP/1.1" 404 4925
"GET /favicon.png HTTP/1.1" 404 4925
"GET / HTTP/1.1" 200 8224
"GET / HTTP/1.1" 200 8224
"GET /static/img/startup.jpg HTTP/1.1" 404 1669
"GET /static/img/startup.jpg HTTP/1.1" 404 1669
"GET /admin/ HTTP/1.1" 302 0
"GET /admin/ HTTP/1.1" 302 0
"GET /admin/login/?next=/admin/ HTTP/1.1" 200 1918
"GET /admin/login/?next=/admin/ HTTP/1.1" 200 1918
"GET /static/admin/css/base.css HTTP/1.1" 200 16378
"GET /static/admin/css/base.css HTTP/1.1" 200 16378
"GET /static/admin/css/login.css HTTP/1.1" 200 1233
"GET /static/admin/css/login.css HTTP/1.1" 200 1233
"GET /static/admin/css/responsive.css HTTP/1.1" 200 18052
"GET /static/admin/css/responsive.css HTTP/1.1" 200 18052
"GET /static/admin/css/fonts.css HTTP/1.1" 200 423
"GET /static/admin/css/fonts.css HTTP/1.1" 200 423
"GET /static/admin/fonts/Roboto-Light-webfont.woff HTTP/1.1" 200 85692
"GET /static/admin/fonts/Roboto-Light-webfont.woff HTTP/1.1" 200 85692
Not Found: /favicon.ico
Not Found: /favicon.ico
"GET /static/admin/fonts/Roboto-Regular-webfont.woff HTTP/1.1" 200 85876
"GET /static/admin/fonts/Roboto-Regular-webfont.woff HTTP/1.1" 200 85876
"GET /favicon.ico HTTP/1.1" 404 4925
"GET /favicon.ico HTTP/1.1" 404 4925
"POST /admin/login/?next=/admin/ HTTP/1.1" 302 0
"POST /admin/login/?next=/admin/ HTTP/1.1" 302 0
"GET /admin/ HTTP/1.1" 200 4375
"GET /admin/ HTTP/1.1" 200 4375
"GET /static/admin/css/dashboard.css HTTP/1.1" 200 412
"GET /static/admin/css/dashboard.css HTTP/1.1" 200 412
"GET /static/admin/img/icon-changelink.svg HTTP/1.1" 200 380
"GET /static/admin/img/icon-changelink.svg HTTP/1.1" 200 380
"GET /static/admin/img/icon-addlink.svg HTTP/1.1" 200 331
"GET /static/admin/img/icon-addlink.svg HTTP/1.1" 200 331
"GET /static/admin/fonts/Roboto-Bold-webfont.woff HTTP/1.1" 200 86184
"GET /static/admin/fonts/Roboto-Bold-webfont.woff HTTP/1.1" 200 86184
"GET /admin/jobs/job/add/ HTTP/1.1" 200 12161
"GET /admin/jobs/job/add/ HTTP/1.1" 200 12161
"GET /static/admin/js/calendar.js HTTP/1.1" 200 7777
"GET /static/admin/js/calendar.js HTTP/1.1" 200 7777
"GET /static/admin/css/forms.css HTTP/1.1" 200 8518
"GET /static/admin/css/forms.css HTTP/1.1" 200 8518
"GET /static/admin/js/core.js HTTP/1.1" 200 5723
"GET /static/admin/js/core.js HTTP/1.1" 200 5723
"GET /static/admin/js/jquery.init.js HTTP/1.1" 200 363
"GET /static/admin/js/jquery.init.js HTTP/1.1" 200 363
"GET /admin/jsi18n/ HTTP/1.1" 200 3223
"GET /admin/jsi18n/ HTTP/1.1" 200 3223
"GET /static/admin/js/admin/RelatedObjectLookups.js HTTP/1.1" 200 6918
"GET /static/admin/js/admin/RelatedObjectLookups.js HTTP/1.1" 200 6918
"GET /static/admin/js/admin/DateTimeShortcuts.js HTTP/1.1" 200 20232
"GET /static/admin/js/admin/DateTimeShortcuts.js HTTP/1.1" 200 20232
"GET /static/admin/js/vendor/jquery/jquery.js HTTP/1.1" 200 280364
"GET /static/admin/js/vendor/jquery/jquery.js HTTP/1.1" 200 280364
"GET /static/admin/js/actions.js HTTP/1.1" 200 6766
"GET /static/admin/js/actions.js HTTP/1.1" 200 6766
"GET /static/admin/css/widgets.css HTTP/1.1" 200 10322
"GET /static/admin/css/widgets.css HTTP/1.1" 200 10322
"GET /static/admin/js/change_form.js HTTP/1.1" 200 712
"GET /static/admin/js/change_form.js HTTP/1.1" 200 712
"GET /static/admin/js/urlify.js HTTP/1.1" 200 8941
"GET /static/admin/js/urlify.js HTTP/1.1" 200 8941
"GET /static/admin/js/prepopulate.js HTTP/1.1" 200 1530
"GET /static/admin/js/prepopulate.js HTTP/1.1" 200 1530
"GET /static/admin/js/vendor/xregexp/xregexp.js HTTP/1.1" 200 128820
"GET /static/admin/js/vendor/xregexp/xregexp.js HTTP/1.1" 200 128820
"GET /static/admin/js/prepopulate_init.js HTTP/1.1" 200 495
"GET /static/admin/js/prepopulate_init.js HTTP/1.1" 200 495
"GET /static/admin/img/icon-calendar.svg HTTP/1.1" 200 1086
"GET /static/admin/img/icon-calendar.svg HTTP/1.1" 200 1086
"GET /static/admin/img/icon-clock.svg HTTP/1.1" 200 677
"GET /static/admin/img/icon-clock.svg HTTP/1.1" 200 677
"GET /admin/ HTTP/1.1" 200 4375
"GET /admin/ HTTP/1.1" 200 4375
"GET /admin/jobs/skill/ HTTP/1.1" 200 3174
"GET /admin/jobs/skill/ HTTP/1.1" 200 3174
"GET /static/admin/css/changelists.css HTTP/1.1" 200 6190
"GET /static/admin/css/changelists.css HTTP/1.1" 200 6190
"GET /admin/jsi18n/ HTTP/1.1" 200 3223
"GET /admin/jsi18n/ HTTP/1.1" 200 3223
"GET /static/admin/img/tooltag-add.svg HTTP/1.1" 200 331
"GET /static/admin/img/tooltag-add.svg HTTP/1.1" 200 331
"GET /admin/jobs/skill/add/ HTTP/1.1" 200 4548
"GET /admin/jobs/skill/add/ HTTP/1.1" 200 4548
"GET /admin/jsi18n/ HTTP/1.1" 200 3223
"GET /admin/jsi18n/ HTTP/1.1" 200 3223
"POST /admin/jobs/skill/add/ HTTP/1.1" 302 0
"POST /admin/jobs/skill/add/ HTTP/1.1" 302 0
"GET /admin/jobs/skill/ HTTP/1.1" 200 4518
"GET /admin/jobs/skill/ HTTP/1.1" 200 4518
"GET /admin/jsi18n/ HTTP/1.1" 200 3223
"GET /admin/jsi18n/ HTTP/1.1" 200 3223
"GET /static/admin/img/icon-yes.svg HTTP/1.1" 200 436
"GET /static/admin/img/icon-yes.svg HTTP/1.1" 200 436
Watching for file changes with StatReloader
Watching for file changes with StatReloader
"GET / HTTP/1.1" 200 8224
"GET / HTTP/1.1" 200 8224
"GET /static/img/startup.jpg HTTP/1.1" 404 1669
"GET /static/img/startup.jpg HTTP/1.1" 404 1669
Not Found: /favicon.png
Not Found: /favicon.png
"GET /favicon.png HTTP/1.1" 404 4925
"GET /favicon.png HTTP/1.1" 404 4925
"GET /admin/ HTTP/1.1" 302 0
"GET /admin/ HTTP/1.1" 302 0
"GET /admin/login/?next=/admin/ HTTP/1.1" 200 1918
"GET /admin/login/?next=/admin/ HTTP/1.1" 200 1918
Not Found: /favicon.ico
Not Found: /favicon.ico
"GET /favicon.ico HTTP/1.1" 404 4925
"GET /favicon.ico HTTP/1.1" 404 4925
"POST /admin/login/?next=/admin/ HTTP/1.1" 302 0
"POST /admin/login/?next=/admin/ HTTP/1.1" 302 0
"GET /admin/ HTTP/1.1" 200 4692
"GET /admin/ HTTP/1.1" 200 4692
"GET /admin/jobs/skill/ HTTP/1.1" 200 4334
"GET /admin/jobs/skill/ HTTP/1.1" 200 4334
"GET /admin/jsi18n/ HTTP/1.1" 200 3223
"GET /admin/jsi18n/ HTTP/1.1" 200 3223
"GET /admin/ HTTP/1.1" 200 4692
"GET /admin/ HTTP/1.1" 200 4692
"GET /admin/jobs/job/ HTTP/1.1" 200 3160
"GET /admin/jobs/job/ HTTP/1.1" 200 3160
"GET /admin/jsi18n/ HTTP/1.1" 200 3223
"GET /admin/jsi18n/ HTTP/1.1" 200 3223
"GET /admin/ HTTP/1.1" 200 4692
"GET /admin/ HTTP/1.1" 200 4692
"GET /admin/jobs/skill/ HTTP/1.1" 200 4334
"GET /admin/jobs/skill/ HTTP/1.1" 200 4334
"GET /admin/jsi18n/ HTTP/1.1" 200 3223
"GET /admin/jsi18n/ HTTP/1.1" 200 3223
"GET /admin/ HTTP/1.1" 200 4692
"GET /admin/ HTTP/1.1" 200 4692
